Workbook

Sheet _Output
B1: in scope | C1: type | D1: answer | E1: importance | F1: NIST mapping (CSF 1.1) | G1: NIST in scope (CSF 1.1) | H1: factor (SUM = MIN score) | I1: total score | J1: MAX score | K1: final score | L1: remarks
A2: SOC-CMM - Business Domain
A3: B1 - Business Drivers
A4: B 1.1 | B4: 1 | C4: M | D4: 0 | E4: 3 | F4: ID.BE-5 | G4: =IF(B4=1,F4,"") -> ID.BE-5 | H4: =VLOOKUP(E4,'_Score matrix'!$B$31:$C$35,2,FALSE) -> 1 | I4: =D4*H4 -> 0 | J4: =5*H4 -> 5 | K4: =IF(ROUND(100*(I4-H4)/(J4-H4),2) < 0, 0, ROUND(100*(I4-H4)/(J4-H4),2)) -> 0
A5: B 1.2 | B5: 1 | C5: M | D5: 0 | E5: 3 | F5: ID.BE-5 | G5: =IF(B5=1,F5,"") -> ID.BE-5 | H5: =VLOOKUP(E5,'_Score matrix'!$B$31:$C$35,2,FALSE) -> 1 | I5: =D5*H5 -> 0 | J5: =5*H5 -> 5 | K5: =IF(ROUND(100*(I5-H5)/(J5-H5),2) < 0, 0, ROUND(100*(I5-H5)/(J5-H5),2)) -> 0
A6: B 1.3 | B6: 1 | C6: M | D6: 0 | E6: 3 | F6: ID.BE-5 | G6: =IF(B6=1,F6,"") -> ID.BE-5 | H6: =VLOOKUP(E6,'_Score matrix'!$B$31:$C$35,2,FALSE) -> 1 | I6: =D6*H6 -> 0 | J6: =5*H6 -> 5 | K6: =IF(ROUND(100*(I6-H6)/(J6-H6),2) < 0, 0, ROUND(100*(I6-H6)/(J6-H6),2)) -> 0
A7: B 1.4 | B7: 1 | C7: M | D7: 0 | E7: 3 | F7: ID.BE-5 | G7: =IF(B7=1,F7,"") -> ID.BE-5 | H7: =VLOOKUP(E7,'_Score matrix'!$B$31:$C$35,2,FALSE) -> 1 | I7: =D7*H7 -> 0 | J7: =5*H7 -> 5 | K7: =IF(ROUND(100*(I7-H7)/(J7-H7),2) < 0, 0, ROUND(100*(I7-H7)/(J7-H7),2)) -> 0
A8: B 1.5 | B8: 1 | C8: M | D8: 0 | E8: 3 | F8: ID.BE-4 | G8: =IF(B8=1,F8,"") -> ID.BE-4 | H8: =VLOOKUP(E8,'_Score matrix'!$B$31:$C$35,2,FALSE) -> 1 | I8: =D8*H8 -> 0 | J8: =5*H8 -> 5 | K8: =IF(ROUND(100*(I8-H8)/(J8-H8),2) < 0, 0, ROUND(100*(I8-H8)/(J8-H8),2)) -> 0
A9: SUM | D9: =SUMIFS(D:D,$A:$A,"B 1*",$B:$B,1,$C:$C,"M",$L:$L,"<>NIST MAPPING") -> 0 | E9: =SUMIFS(E:E,$A:$A,"B 1*",$B:$B,1,$C:$C,"M",$L:$L,"<>NIST MAPPING") -> 15 | F9: =SUMIFS(F:F,$A:$A,"B 1*",$B:$B,1,$C:$C,"M",$L:$L,"<>NIST MAPPING") -> 0 | G9: =SUMIFS(G:G,$A:$A,"B 1*",$B:$B,1,$C:$C,"M",$L:$L,"<>NIST MAPPING") -> 0 | H9: =SUMIFS(H:H,$A:$A,"B 1*",$B:$B,1,$C:$C,"M",$L:$L,"<>NIST MAPPING") -> 5 | I9: =SUMIFS(I:I,$A:$A,"B 1*",$B:$B,1,$C:$C,"M",$L:$L,"<>NIST MAPPING") -> 0 | J9: =SUMIFS(J:J,$A:$A,"B 1*",$B:$B,1,$C:$C,"M",$L:$L,"<>NIST MAPPING") -> 25 | K9: =IF(ROUND(100*(I9-H9)/(J9-H9),2) < 0, 0, ROUND(100*(I9-H9)/(J9-H9),2)) -> 0
A11: B2 - Customers
A12: B 2.1 | B12: 1 | C12: M | D12: 0 | E12: 3 | F12: ID.AM-6 | G12: =IF(B12=1,F12,"") -> ID.AM-6 | H12: =VLOOKUP(E12,'_Score matrix'!$B$31:$C$35,2,FALSE) -> 1 | I12: =D12*H12 -> 0 | J12: =5*H12 -> 5
A13: B 2.2 | L13: not used in calculations, but to determine 2.1
A14: B 2.2.1 | D14: 1
A15: B 2.2.2 | D15: 1
A16: B 2.2.3 | D16: 1
A17: B 2.2.4 | D17: 1
A18: B 2.2.5 | D18: 1
A19: B 2.2.6 | D19: 1
A20: B 2.2.7 | D20: 1
A21: B 2.2.8
A22: B 2.3 | B22: 1 | C22: M | D22: 0 | E22: 3 | F22: ID.AM-6 | G22: =IF(B22=1,F22,"") -> ID.AM-6 | H22: =VLOOKUP(E22,'_Score matrix'!$B$31:$C$35,2,FALSE) -> 1 | I22: =D22*H22 -> 0 | J22: =5*H22 -> 5
A23: B 2.4 | B23: 1 | C23: M | D23: 0 | E23: 3 | F23: ID.AM-6 | G23: =IF(B23=1,F23,"") -> ID.AM-6 | H23: =VLOOKUP(E23,'_Score matrix'!$B$31:$C$35,2,FALSE) -> 1 | I23: =D23*H23 -> 0 | J23: =5*H23 -> 5
A24: B 2.5 | B24: 1 | C24: M | D24: 0 | E24: 3 | F24: ID.AM-6 | G24: =IF(B24=1,F24,"") -> ID.AM-6 | H24: =VLOOKUP(E24,'_Score matrix'!$B$31:$C$35,2,FALSE) -> 1 | I24: =D24*H24 -> 0 | J24: =5*H24 -> 5
A25: B 2.6 | B25: 1 | C25: M | D25: 0 | E25: 3 | F25: ID.AM-6 | G25: =IF(B25=1,F25,"") -> ID.AM-6 | H25: =VLOOKUP(E25,'_Score matrix'!$B$31:$C$35,2,FALSE) -> 1 | I25: =D25*H25 -> 0 | J25: =5*H25 -> 5
A26: B 2.7 | B26: 1 | C26: M | D26: 0 | E26: 3 | F26: ID.AM-6 | G26: =IF(B26=1,F26,"") -> ID.AM-6 | H26: =VLOOKUP(E26,'_Score matrix'!$B$31:$C$35,2,FALSE) -> 1 | I26: =D26*H26 -> 0 | J26: =5*H26 -> 5
A27: SUM | D27: =SUMIFS(D:D,$A:$A,"B 2*",$B:$B,1,$C:$C,"M",$L:$L,"<>NIST MAPPING") -> 0 | E27: =SUMIFS(E:E,$A:$A,"B 2*",$B:$B,1,$C:$C,"M",$L:$L,"<>NIST MAPPING") -> 18 | F27: =SUMIFS(F:F,$A:$A,"B 2*",$B:$B,1,$C:$C,"M",$L:$L,"<>NIST MAPPING") -> 0 | G27: =SUMIFS(G:G,$A:$A,"B 2*",$B:$B,1,$C:$C,"M",$L:$L,"<>NIST MAPPING") -> 0 | H27: =SUMIFS(H:H,$A:$A,"B 2*",$B:$B,1,$C:$C,"M",$L:$L,"<>NIST MAPPING") -> 6 | I27: =SUMIFS(I:I,$A:$A,"B 2*",$B:$B,1,$C:$C,"M",$L:$L,"<>NIST MAPPING") -> 0 | J27: =SUMIFS(J:J,$A:$A,"B 2*",$B:$B,1,$C:$C,"M",$L:$L,"<>NIST MAPPING") -> 30 | K27: =IF(ROUND(100*(I27-H27)/(J27-H27),2) < 0, 0, ROUND(100*(I27-H27)/(J27-H27),2)) -> 0
A29: B3 - SOC Charter
A30: B 3.1 | B30: 1 | C30: M | D30: 0 | E30: 3 | F30: ID.BE-3 | G30: =IF(B30=1,F30,"") -> ID.BE-3 | H30: =VLOOKUP(E30,'_Score matrix'!$B$31:$C$35,2,FALSE) -> 1 | I30: =D30*H30 -> 0 | J30: =5*H30 -> 5
A31: B 3.2 | D31: ='Business - CHT'!L23 -> Incomplete | L31: not used in calculations, but to determine 3.1
A32: B 3.2.1 | D32: 1
A33: B 3.2.2 | D33: 1
A34: B 3.2.3 | D34: 1
A35: B 3.2.4 | D35: 1
A36: B 3.2.5 | D36: 1
A37: B 3.2.6 | D37: 1
A38: B 3.2.7 | D38: 1
A39: B 3.2.8 | D39: 1
A40: B 3.2.9 | D40: 1
A41: B 3.2.10 | D41: 1
A42: B 3.2.11 | D42: 1
...

Sheet Index
B1: Index
B3: Index
B9: Click on any section name to proceed directly to that part of the assessment
B10: Domain | D10: Section | I10: Questions remaining
B11: Introduction | D11: 1. Introduction | I11: N/A
D12: 2. Usage | I12: N/A
D13: 3. Change notes | J13: N/A
I14: Questions remaining
B15: General | D15: 1. Profile | I15: N/A
D16: 2. Scope | I16: N/A
I17: Questions remaining
B18: Business | D18: 1. Business drivers | I18: =CONCATENATE(COUNTIFS(_Output!A:A,"B 1*",_Output!B:B,1,_Output!L:L,"<>NIST MAPPING",_Output!D:D, 0,_Output!E:E, ">1"),"/", COUNTIFS(_Output!A:A,"B 1*",_Output!B:B,1,_Output!L:L,"<>NIST MAPPING",_Output!E:E, ">1")) -> 5/5
D19: 2. Customers | I19: =CONCATENATE(COUNTIFS(_Output!A:A,"B 2*",_Output!B:B,1,_Output!L:L,"<>NIST MAPPING",_Output!D:D, 0,_Output!E:E, ">1"),"/",COUNTIFS(_Output!A:A,"B 2*",_Output!B:B,1,_Output!L:L,"<>NIST MAPPING",_Output!E:E, ">1")) -> 6/6
D20: 3. Charter | I20: =CONCATENATE(COUNTIFS(_Output!A:A,"B 3*",_Output!B:B,1,_Output!L:L,"<>NIST MAPPING",_Output!D:D, 0,_Output!E:E, ">1"),"/", COUNTIFS(_Output!A:A,"B 3*",_Output!B:B,1,_Output!L:L,"<>NIST MAPPING",_Output!E:E, ">1")) -> 4/4
D21: 4. Governance | I21: =CONCATENATE(COUNTIFS(_Output!A:A,"B 4*",_Output!B:B,1,_Output!L:L,"<>NIST MAPPING",_Output!D:D, 0,_Output!E:E, ">1"),"/",COUNTIFS(_Output!A:A,"B 4*",_Output!B:B,1,_Output!L:L,"<>NIST MAPPING",_Output!E:E, ">1")) -> 9/9
D22: 5. Privacy & Policy | I22: =CONCATENATE(COUNTIFS(_Output!A:A,"B 5*",_Output!B:B,1,_Output!L:L,"<>NIST MAPPING",_Output!D:D, 0,_Output!E:E, ">1"),"/",COUNTIFS(_Output!A:A,"B 5*",_Output!B:B,1,_Output!L:L,"<>NIST MAPPING",_Output!E:E, ">1")) -> 10/10
I23: Questions remaining
B24: People | D24: 1. Employees | I24: =CONCATENATE(COUNTIFS(_Output!A:A,"P 1*",_Output!B:B,1,_Output!L:L,"<>NIST MAPPING",_Output!D:D, 0,_Output!E:E, ">1"),"/",COUNTIFS(_Output!A:A,"P 1*",_Output!B:B,1,_Output!L:L,"<>NIST MAPPING",_Output!E:E, ">1")) -> 8/8
D25: 2. Roles and Hierarchy | I25: =CONCATENATE(COUNTIFS(_Output!A:A,"P 2*",_Output!B:B,1,_Output!L:L,"<>NIST MAPPING",_Output!D:D, 0,_Output!E:E, ">1"),"/",COUNTIFS(_Output!A:A,"P 2*",_Output!B:B,1,_Output!L:L,"<>NIST MAPPING",_Output!E:E, ">1")) -> 8/8
D26: 3. People Management | I26: =CONCATENATE(COUNTIFS(_Output!A:A,"P 3*",_Output!B:B,1,_Output!L:L,"<>NIST MAPPING",_Output!D:D, 0,_Output!E:E, ">1"),"/",COUNTIFS(_Output!A:A,"P 3*",_Output!B:B,1,_Output!L:L,"<>NIST MAPPING",_Output!E:E, ">1")) -> 14/14
D27: 4. Knowledge Management | I27: =CONCATENATE(COUNTIFS(_Output!A:A,"P 4*",_Output!B:B,1,_Output!L:L,"<>NIST MAPPING",_Output!D:D, 0,_Output!E:E, ">1"),"/",COUNTIFS(_Output!A:A,"P 4*",_Output!B:B,1,_Output!L:L,"<>NIST MAPPING",_Output!E:E, ">1")) -> 8/8
D28: 5. Training & Education | I28: =CONCATENATE(COUNTIFS(_Output!A:A,"P 5*",_Output!B:B,1,_Output!L:L,"<>NIST MAPPING",_Output!D:D, 0,_Output!E:E, ">1"),"/",COUNTIFS(_Output!A:A,"P 5*",_Output!B:B,1,_Output!L:L,"<>NIST MAPPING",_Output!E:E, ">1")) -> 7/7
I29: Questions remaining
B30: Process | D30: 1. SOC Management | I30: =CONCATENATE(COUNTIFS(_Output!A:A,"M 1*",_Output!B:B,1,_Output!L:L,"<>NIST MAPPING",_Output!D:D, 0,_Output!E:E, ">1"),"/",COUNTIFS(_Output!A:A,"M 1*",_Output!B:B,1,_Output!L:L,"<>NIST MAPPING",_Output!E:E, ">1")) -> 9/9
D31: 2. Operations and Facilities | I31: =CONCATENATE(COUNTIFS(_Output!A:A,"M 2*",_Output!B:B,1,_Output!L:L,"<>NIST MAPPING",_Output!D:D, 0,_Output!E:E, ">1"),"/",COUNTIFS(_Output!A:A,"M 2*",_Output!B:B,1,_Output!L:L,"<>NIST MAPPING",_Output!E:E, ">1")) -> 31/31
D32: 3. Reporting & Communication | I32: =CONCATENATE(COUNTIFS(_Output!A:A,"M 3*",_Output!B:B,1,_Output!L:L,"<>NIST MAPPING",_Output!D:D, 0,_Output!E:E, ">1"),"/", COUNTIFS(_Output!A:A,"M 3*",_Output!B:B,1,_Output!L:L,"<>NIST MAPPING",_Output!E:E, ">1")) -> 17/17
D33: 4. Use Case Management | I33: =CONCATENATE(COUNTIFS(_Output!A:A,"M 4*",_Output!B:B,1,_Output!L:L,"<>NIST MAPPING",_Output!D:D, 0,_Output!E:E, ">1"),"/",COUNTIFS(_Output!A:A,"M 4*",_Output!B:B,1,_Output!L:L,"<>NIST MAPPING",_Output!E:E, ">1")) -> 20/20
D34: 5. Detection Engineering & Validation | I34: =CONCATENATE(COUNTIFS(_Output!A:A,"M 5*",_Output!B:B,1,_Output!L:L,"<>NIST MAPPING",_Output!D:D, 0, _Output!E:E, ">1"),"/",COUNTIFS(_Output!A:A,"M 5*",_Output!B:B,1,_Output!L:L,"<>NIST MAPPING", _Output!E:E, ">1")) -> 18/18
I35: Questions remaining
B36: Technology | D36: 1. SIEM / UEBA | I36: =CONCATENATE(COUNTIFS(_Output!A:A,"T 1*",_Output!B:B,1,_Output!L:L,"<>NIST MAPPING",_Output!D:D, 0, _Output!E:E, ">1"),"/",COUNTIFS(_Output!A:A,"T 1*",_Output!B:B,1,_Output!L:L,"<>NIST MAPPING", _Output!E:E, ">1")) -> 60/60
D37: 2. NDR | I37: =CONCATENATE(COUNTIFS(_Output!A:A,"T 2*",_Output!B:B,1,_Output!L:L,"<>NIST MAPPING",_Output!D:D, 0, _Output!E:E, ">1"),"/",COUNTIFS(_Output!A:A,"T 2*",_Output!B:B,1,_Output!L:L,"<>NIST MAPPING",_Output!E:E, ">1")) -> 56/56
D38: 3. EDR | I38: =CONCATENATE(COUNTIFS(_Output!A:A,"T 3*",_Output!B:B,1,_Output!L:L,"<>NIST MAPPING",_Output!D:D, 0, _Output!E:E, ">1"),"/",COUNTIFS(_Output!A:A,"T 3*",_Output!B:B,1,_Output!L:L,"<>NIST MAPPING", _Output!E:E, ">1")) -> 72/72
D39: 4. SOAR | I39: =CONCATENATE(COUNTIFS(_Output!A:A,"T 4*",_Output!B:B,1,_Output!L:L,"<>NIST MAPPING",_Output!D:D, 0,_Output!E:E, ">1"),"/",COUNTIFS(_Output!A:A,"T 4*",_Output!B:B,1,_Output!L:L,"<>NIST MAPPING",_Output!E:E, ">1")) -> 46/46
I40: Questions remaining
B41: Services | D41: 1. Security Monitoring | I41: =CONCATENATE(COUNTIFS(_Output!A:A,"S 1*",_Output!B:B,1,_Output!L:L,"<>NIST MAPPING",_Output!D:D, 0, _Output!E:E, ">1"),"/",COUNTIFS(_Output!A:A,"S 1*",_Output!B:B,1,_Output!L:L,"<>NIST MAPPING",_Output!E:E, ">1")) -> 40/40
D42: 2. Security Incident Management | I42: =CONCATENATE(COUNTIFS(_Output!A:A,"S 2*",_Output!B:B,1,_Output!L:L,"<>NIST MAPPING",_Output!D:D, 0, _Output!E:E, ">1"),"/",COUNTIFS(_Output!A:A,"S 2*",_Output!B:B,1,_Output!L:L,"<>NIST MAPPING", _Output!E:E, ">1")) -> 49/49
D43: 3. Security Analysis and Forensics | I43: =CONCATENATE(COUNTIFS(_Output!A:A,"S 3*",_Output!B:B,1,_Output!L:L,"<>NIST MAPPING",_Output!D:D, 0, _Output!E:E, ">1"),"/",COUNTIFS(_Output!A:A,"S 3*",_Output!B:B,1,_Output!L:L,"<>NIST MAPPING", _Output!E:E, ">1")) -> 38/38
D44: 4. Threat Intelligence | I44: =CONCATENATE(COUNTIFS(_Output!A:A,"S 4*",_Output!B:B,1,_Output!L:L,"<>NIST MAPPING",_Output!D:D, 0, _Output!E:E, ">1"),"/",COUNTIFS(_Output!A:A,"S 4*",_Output!B:B,1,_Output!L:L,"<>NIST MAPPING", _Output!E:E, ">1")) -> 44/44
D45: 5. Threat Hunting | I45: =CONCATENATE(COUNTIFS(_Output!A:A,"S 5*",_Output!B:B,1,_Output!L:L,"<>NIST MAPPING",_Output!D:D, 0, _Output!E:E, ">1"),"/",COUNTIFS(_Output!A:A,"S 5*",_Output!B:B,1,_Output!L:L,"<>NIST MAPPING",_Output!E:E, ">1")) -> 35/35
D46: 6. Vulnerability Management | I46: =CONCATENATE(COUNTIFS(_Output!A:A,"S 6*",_Output!B:B,1,_Output!L:L,"<>NIST MAPPING",_Output!D:D, 0, _Output!E:E, ">1"),"/",COUNTIFS(_Output!A:A,"S 6*",_Output!B:B,1,_Output!L:L,"<>NIST MAPPING", _Output!E:E, ">1")) -> 33/33
...

Sheet Introduction - INT
B1: Introduction
B3: 1. Introduction
B4: 2. Usage
B5: 3. Change notes
B19: General information
B20: Author | G20: Rob van Os
B21: Site | G21: https://www.soc-cmm.com/
B22: Contact | G22: info@SOC-CMM.com
B23: Version | G23: 2.3.2, advanced version
B24: Date | G24: September 20, 2023
B26: Background
B27: The SOC-CMM is a capability maturity model that can be used to perform a self-assessment of your Security Operations Center (SOC). The model is based on review conducted on literature regarding SOC setup and existing SOC models as well as literature on specific elements within a SOC. The literature analysis was then validated by questioning several Security Operations Centers in different sectors and on different maturity levels to determine which elements were actually in place. The output from the survey, combined with the initial analysis is the basis for this self-assessment. For more information regarding the scientific background and the literature used to create the SOC-CMM self-assessment tool, please refer to the thesis document as available through: https://www.soc-cmm.com/ If you have any questions or comments regarding the contents of this document, please use the above information to contact me. There is also a SOC-CMM community where you can post your questions or suggestions for improvement or extension of the SOC-CMM.
B36: Purpose and intended audience
B37: The purpose of the SOC-CMM is to gain insight into the strengths and weaknesses of the SOC. This enables the SOC management to make informed decisions about which elements of the SOC require additional attention and/or budget. By regularly assessing the SOC for maturity and capability, progress can be monitored. Besides the primary purpose of performing an assessment of the SOC, the assessment can also be used for extensive discussions about the SOC and can thus provide valuable insights. This tool is intended for use by SOC and security managers, experts within the SOC and SOC consultants.
B44: Navigation
B45: Navigation through this tool is done using the navigation bar at the top of each page. Each of the numbered sections can be clicked to proceed directly to that section. Furthermore, the icons can be used to navigate through sections within a domain and between domains. The icons are as follows:
C47: navigate to previous domain | H47: navigate to previous section within the domain
C49: navigate to index | H49: navigate to next section within the domain
C51: navigate to next domain | H51: navigate directly to results
B53: Assessment Model
B54: The assessment model consists of 5 domains and 25 aspects. All domains are evaluated for maturity (blue), only technology and services are evaluated for both maturity and capability (purple)
B74: Maturity Levels
B75: CMMI defines maturity as a means for an organization "to characterize its performance" for a specific entity (here: the SOC). The SOC-CMM calculates a maturity score using 6 maturity levels: - Level 0: non-existent - Level 1: initial - Level 2: managed - Level 3: defined - Level 4: quantitatively managed - Level 5: optimizing These maturity levels are measured across 5 domains: business, people, process, technology and services. The maturity levels as implemented in this tool are not staged with pre-requisites for each level. Instead, every element adds individually to the maturity score: a continuous maturity model.
B84: Capability Levels
B85: Capabilities are indicators of completeness. In essence, capabilities can support maturity. The SOC-CMM calculates a capability score using 4 capability levels, similar to CMMi: - Level 0: incomplete - Level 1: performed - Level 2: managed - Level 3: defined These capability levels have a strong technical focus and are measured across 2 domains: technology and services. Similar to maturity levels, progress to a higher capability level is continuous. There are no prerequisites for advancing to a higher level, thus the capability growth is continuous as well.
B93: Disclaimer
B94: The SOC-CMM is provided without warranty of any kind. The author of the document cannot assure its accuracy and is not liable for any cost as a result of decisions based on the output of this tool. The usage of this tool does not in any way entitle the user to support or consultancy. By using this tool, you agree to these conditions.
B97: License
B98: Copyright (C) 2021 - SOC-CMM The SOC-CMM advanced version is part of the SOC-CMM. The SOC-CMM is free software, released under the CC SA-BY license: https://creativecommons.org/licenses/by-sa/4.0/ You are free to: Share — copy and redistribute the material in any medium or format Adapt — remix, transform, and build upon the material for any purpose, even commercially. Under the following terms: Attribution — You must give appropriate credit, provide a link to the license, and indicate if changes were made. You may do so in any reasonable manner, but not in any way that suggests the licensor endorses you or your use. ShareAlike — If you remix, transform, or build upon the material, you must distribute your contributions under the same license as the original. No additional restrictions — You may not apply legal terms or technological measures that legally restrict others from doing anything the license permits. This license is acceptable for Free Cultural Works. The licensor cannot revoke these freedoms as long as you follow the license terms. This program is distributed in the hope that it will be useful, but WITHOUT ANY WARRANTY; without even the implied warranty of MERCHANTABILITY or FITNESS FOR A PARTICULAR PURPOSE.

Sheet Introduction - USG
B1: Introduction
B3: 1. Introduction
B4: 2. Usage
B5: 3. Change notes
B9: How to use the SOC-CMM
B10: The SOC-CMM has an embedded workflow that guides the assessment. First, the profile sheet is filled in and the scope for assessment is selected. Then, the 5 domains of the SOC-CMM (i.e. Business, People, Process, Technology and Services) are each evaluated in separate sections of this tool. The evaluation is based on questions that can be answered using a drop-down that presents a 5-point scale. This scale relates to the maturity level as explained below under 'Scoring mechanism'. This tool should be used by assessing each sheet in order. When all domains are completed, the sheet 'Results' will provide you with the total scoring and detailed scoring for each domain. A sheet 'Next steps' is also included to provide pointers for follow-up. In the advanced version only, there is also a weighing mechanism in place. For each question, the importance of that element can be changed. The standard importance is 'normal', which means that the score is not modified. Changing to importance to 'low' will cause the element to have less impact on the score. Changing it to 'High' or 'Critical' will cause the element to have more impact on the score. Setting it to 'none' will ignore the element in scoring entirely, as explained under 'Weighing mechanism'. This feature should be used with care. Some additional remarks regarding the usage of the SOC-CMM: 1. Some elements are not used directly for scoring (this is also indicated), but are a guideline for answering other questions. These elements have a lighter color. For example, question 3.1 (part of maturity score) can be answered by using the elements in 3.2 (not part of maturity score) as a guideline. 2. Elements with a green color are calculated fields. These will be filled in automatically by filling in those parts of the assessment. 3. The services and Technology domains evaluate both maturity and capability. These capabilities do not have a 5-point scale and an importance, but use a 6-point scale instead. This is to reduce the amount of clicks and answers. The sixth element in the scale is 'not required'. Use this if you do not feel like you need that particular capability and to exclude it from scoring. 4. Every sheet has a part where you can fill in some comments or remarks. Discussing the questions in this self-assessments will likely uncover some improvements. This is added value for a self-assessment, so it is worthwhile to create notes. 5. The weighing mechanisms allows for manipulation of the maturity score. Therefore, it is important to strongly consider and possibly document why you wish to deviate from the standard. The goal of the SOC-CMM is to provide insight into strengths and weaknesses and to improve the SOC, not to obtain the highest score possible. 6. The NIST score is calculated automatically as explained below 7. Performing a full SOC-CMM assessment can take a significant amount of time, depending on the level of detail you put into the assessment. Before you start, ensure that you have allocated sufficient time. A way to reduce effort is to have a single knowledgeable SOC employee perform a quick scan and subsequently focus on areas that are debatable. Also, reducing scope for an initial assessment is a way to reduce the assessment effort.
B31: Scoring mechanism
B32: Each question that is part of the maturity scoring can be answered by selecting one of 5 options. These options vary based on the type of question. For example, for questions regarding completeness, the following applies: - Incomplete, score: 0 - Partially complete, score: 1,25 - Averagely complete, score: 2,5 - Mostly complete, score: 3,75 - Fully complete, score: 5 As indicated, the score can be modified by using the weighing mechanism (use with care)
B39: Guidance
B40: For each of the maturity questions, guidance is available. When a value is selected from the dropdown box, guidance for that value is show under the guidance column. This guidance can be used to help determine the correct level. Note that this is truly meant as guidance on interpretation and scoring, not as mandatory and prescriptive.
B43: Weighing mechanism (advanced version only)
B44: The weighing mechanism in the tool works by applying a factor to the element score as follows: - Importance 'None', factor = 0 (not included in scoring) - Importance 'Low', factor = 0.5 (score divided by 2) - Importance 'Normal', factor = 1 (score not affected) - Importance 'High', factor = 2 (score doubled) - Importance 'Critical', factor = 4 (score quadrupled)
... B53: The SOC-CMM is built using standard Excel features without macros. The sheets are not locked or password protected. Therefore, adding colums and rows and applying other changes such as changing guidance or adding elements is possible. To show columns and rows, go to 'View' --> 'Show' and check 'Headings'. To show all the tabs underlying the SOC-CMM, go top 'File' --> 'Options' --> 'Advanced' --> 'Display options' and check 'Show sheet tabs'. Customizing calculations will require understanding of the calculations done in the '_Output' sheet. However, guidance for this type of customization is not provided, as it requires an understanding of the way the SOC-CMM sheets are connected.

Sheet Introduction - CHG
B1: Introduction
B3: 1. Introduction | G3: Version 2.3
B4: 2. Usage | G4: Version 2.2
B5: 3. Change notes
B9: Version 2.3 (scroll down or click top links for previous versions)
B11: Business domain:
C12: Governance
D13: 4.3.13: included SOC risk management into governance elements
D14: 4.7: Added question on governance meetings
D15: 4.7 - 4.10: renumbered to 4.8 - 4.11
C16: Privacy & Policy:
D17: 5.2: SOC policy added as a new question, 5.3 outlines the elements in the policy
D18: 5.4 - 5.11: renumbered from 5.2 - 5.9
B19: People domain:
C20: Roles & hierarchy
D21: 2.2.3: changed security specialist to forensic analyst
D22: 2.2.12: added detection engineer
D23: 2.2.13: added automation engineer
C25: Knowledge management:
D26: Skill matrix questions aggregated into two questions
D27: Knowledge matrix questions aggregated into two questions
D28: Renumbering applied to section
B30: Process domain:
C31: SOC management:
D32: 1.2: guidance updated for this question
D33: 1.6: added a question on continuous improvement
D34: 1.7: added a question on quality assurance
D35: 1.8: added 3 questions on SOC architecture
C37: Operations and facilities:
D38: 2.1: security operations exercises turned into a separate section, additional questions inserted
D39: 2.1.1: renumbered to 2.1.3
D40: 2.1.2 - 2.5.2: renumbered to 2.2.1 - 2.6.2
C42: Reporting & Communication
D43: Report types aggregated into a single question
D44: Metrics types aggregated into a single question
D45: 3.9 - 3.12: renumbered to 3.11 - 3.14
C47: Detection Engineering & Validation:
D48: 5.2.1: changed wording, guidance and remark for this question. Added some example resources
D49: 5.2.7 - 5.2.8: added questions on validation of integrity of data ingestion and log source coverage
B51: Technology domain:
...

Sheet General - PRO
B1: Profile
B3: 1. Profile
B4: 2. Scope
B8: Please fill in the information below to create a short profile of the SOC and the assessment
B10: Assessment Details
B11: Date of assessment
B12: Name(s)
B16: Department(s)
B17: Intended purpose of the assessment
B21: Scope
B26: Organisation & SOC Profile
B27: Business size
... B30: Number of FTE's
B31: SOC model | K31: Follow the sun, hybrid (partially outsourced), centralized, multiple individual SOCs, multi-tiered SOC model
B32: Geographic operation | K32: Regional, National, Continental, Global
B34: Target Maturity (optional)
B35: Target maturity level business domain | G35: 3 | K35: Indicate a score from 1 to 5. Decimals can be used
B36: Target maturity level people domain | G36: 3 | K36: Indicate a score from 1 to 5. Decimals can be used
B37: Target maturity level process domain | G37: 3 | K37: Indicate a score from 1 to 5. Decimals can be used
B38: Target maturity level technology domain | G38: 3 | K38: Indicate a score from 1 to 5. Decimals can be used
B39: Target maturity level services domain | G39: 3 | K39: Indicate a score from 1 to 5. Decimals can be used
B40: Target overall maturity level | G40: =IFERROR(SUM(G35:J39)/5, 0) -> 3
B42: Target Capability (optional)
B43: Target capability level technology domain | G43: 2 | K43: Indicate a score from 1 to 3. Decimals can be used
B44: Target capability level services domain | G44: 2 | K44: Indicate a score from 1 to 3. Decimals can be used
B45: Target overall capability level | G45: =IFERROR(SUM(G43:J44)/COUNT(G43:J44), 0) -> 2
B47: Notes or comments

Sheet General - SCP
B1: Profile
B3: 1. Profile
B4: 2. Scope
B8: Please select the services and technologies that should be included into the assessment. Excluding a service or technology here will exclude it from scoring. Note: changes to these values take some time to process
B10: SOC Tooling (Technology domain) | J10: Remarks
B11: SIEM / UEBA | J11: Security Information and Event management tooling. Used to gather logging information from company assets and correlate events. Also includes User and Entity Behavior Analytics (UEBA)
B12: NDR | J12: Network security solution, used detect network exploits and anomalous network activity and perform network forensics
B13: EDR | J13: End-point security solution, used to prevent, detect en respond to threats on end-points
B14: SOAR | J14: Used to automate workflows and SOC actions, support incident response and orchestrate between different security products
B16: SOC Services (services domain) | J16: Remarks
B17: Security Monitoring | J17: The security monitoring service aims at detecting security incidents and events
B18: Security Incident Management | J18: The security incident management service aims at responding to security incidents in a timely, accurate and organized fashion
B19: Security Analysis | J19: The security analysis service supports security monitoring and security incident management. Analysis includes event analysis and forensic analysis
B20: Threat Intelligence | J20: The threat intelligence service provides information about potential threats that can be used in security monitoring, security incident response, security analysis and threat hunting
B21: Threat Hunting | J21: The hunting service takes a proactive approach to finding threats in the infrastructure. Threat intelligence is often used to guide hunting efforts
B22: Vulnerability Management | J22: The vulnerability management service is used to detect vulnerabilities in assets by discovery and actively scanning assets for known vulnerabilities
B23: Log Management | J23: The log management service is used to collect, store and retain logging. Can be used for compliance purposes as well as investigation purposes

Sheet Business - BSD
B1: Business
B3: 1. Business Drivers | G3: 5. Privacy & Policy
B4: 2. Customers
B5: 3. Charter
B6: 4. Governance
A9: 1 | B9: Business Drivers | L9: Answer | N9: Importance | P9: Guidance | Q9: Remarks
B10: 1.1 | C10: Have you identified the main business drivers? | P10: =VLOOKUP(_Output!D4,_Guidance!B4:C9,2,FALSE) | Q10: Example business drivers: cyber crime prevention, risk reduction, law / regulation, audit / compliance, business continuity
B11: 1.2 | C11: Have you documented the main business drivers? | P11: =VLOOKUP(_Output!D5,_Guidance!B10:C15,2,FALSE) | Q11: Documentation of business drivers is important for demonstrable business alignment
B12: 1.3 | C12: Do you use business drivers in the decision making process? | P12: =VLOOKUP(_Output!D6,_Guidance!B16:C21,2,FALSE) | Q12: e.g. to determine priorities or make decisions regarding the on-boarding of new services or operations
B13: 1.4 | C13: Do you regularly check if the current service catalogue is aligned with business drivers? | P13: =VLOOKUP(_Output!D7,_Guidance!B22:C27,2,FALSE) | Q13: i.e. do you check for services or operations that outside the scope of business drivers?
B14: 1.5 | C14: Have the business drivers been validated with business stakeholders? | P14: =VLOOKUP(_Output!D8,_Guidance!B28:C33,2,FALSE) | Q14: Business stakeholders can be C-level management
B16: Comments and/or Remarks
B17: 1.6 | C17: Specify rationale for chosen values or any additional comments | L17: 1.1
L18: 1.2
L19: 1.3
L20: 1.4
L21: 1.5

Sheet Business - CST
B1: Business
B3: 1. Business Drivers | G3: 5. Privacy & Policy
B4: 2. Customers
B5: 3. Charter
B6: 4. Governance
A9: 2 | B9: Customers | L9: Answer | N9: Importance | P9: Guidance | Q9: Remarks
B10: 2.1 | C10: Have you identified the SOC customers? | P10: =VLOOKUP(_Output!D12,_Guidance!B35:C40,2,FALSE) | Q10: Types of customers, customer requirements / expectations, etc.
B11: 2.2 | C11: Please specify your customers: | Q11: Use this a guideline for answering 2.1 This is also potentially useful for insights and comparison with previous assessments
B12: 2.2.1 | C12: Legal | Q12: Legal department, may be a stakeholder for privacy, or may request forensic investigation to the SOC
B13: 2.2.2 | C13: Audit | Q13: The audit department can be supported by logging provided by the SOC
B14: 2.2.3 | C14: Engineering / R&D | Q14: The engineering departments deal with Intellectual Property that may require additional access monitoring
B15: 2.2.4 | C15: IT | Q15: IT departments can be supported by monitoring for anomalies in their infrastructure and systems
B16: 2.2.5 | C16: Business | Q16: Business should be the most important customer, as all SOC activities ultimately support business processes
B17: 2.2.6 | C17: External customers | Q17: External customers mostly apply to managed service providers
B18: 2.2.7 | C18: (Senior) Management | Q18: Senior management may be a direct SOC customer, depending on organization hierarchy
B19: 2.2.8 | C19: Other customers: | Q19: Specify any additional customers
B20: 2.3 | C20: Have you documented the main SOC customers? | P20: =VLOOKUP(_Output!D22,_Guidance!B41:C46,2,FALSE) | Q20: Formal registration of customer contact details, place in the organization, geolocation, etc.
B21: 2.4 | C21: Do you differentiate output towards these specific customers? | P21: =VLOOKUP(_Output!D23,_Guidance!B47:C52,2,FALSE) | Q21: For example, are communication style and contents to Business customers different than that to IT?
B22: 2.5 | C22: Do you have service level agreements with these customers? | P22: =VLOOKUP(_Output!D24,_Guidance!B53:C58,2,FALSE) | Q22: Service level agreements are used to provide standardized services operating within known boundaries
B23: 2.6 | C23: Do you regularly send updates to your customers? | P23: =VLOOKUP(_Output!D25,_Guidance!B59:C64,2,FALSE) | Q23: For example: changes in service scope or delivery. Can also be reports, dashboards, etc.
B24: 2.7 | C24: Do you actively measure and manage customer satisfaction? | P24: =VLOOKUP(_Output!D26,_Guidance!B65:C70,2,FALSE) | Q24: Understanding customer satisfaction will help to better align with business needs
B26: Comments and/or Remarks
B27: 2.8 | C27: Specify rationale for chosen values or any additional comments | L27: 2.1
L28: 2.3
L29: 2.4
L30: 2.5
L31: 2.6
L32: 2.7

Sheet Business - CHT
B1: Business
B3: 1. Business Drivers | G3: 5. Privacy & Policy
B4: 2. Customers
B5: 3. Charter
B6: 4. Governance
A9: 3 | B9: Charter | L9: Answer | N9: Importance | P9: Guidance | Q9: Remarks
B10: 3.1 | C10: Does the SOC have a formal charter document in place? | P10: =VLOOKUP(_Output!D30,_Guidance!B72:C77,2,FALSE) | Q10: See 3.2 for charter document elements
B11: 3.2 | C11: Please specify elements of the charter document:
B12: 3.2.1 | C12: Mission | Q12: A SOC mission should be established to provide insight into the reason for existence of the SOC
B13: 3.2.2 | C13: Vision | Q13: A vision should be created to determine long-term goals for the SOC
B14: 3.2.3 | C14: Strategy | Q14: A strategy should be in place to show how to meet goals and targets set by mission and vision
B15: 3.2.4 | C15: Service Scope | Q15: Service scope is documented to provide insight into SOC service delivery
B16: 3.2.5 | C16: Deliverables | Q16: The output provided by the SOC, for example: reports, incidents, investigations, advisories, etc.
B17: 3.2.6 | C17: Responsibilities | Q17: Responsibilities of the SOC
B18: 3.2.7 | C18: Accountability | Q18: Accountability for the SOC for actions taken
B19: 3.2.8 | C19: Operational Hours | Q19: Operational hours of the SOC
B20: 3.2.9 | C20: Stakeholders | Q20: All relevant stakeholders for the SOC
B21: 3.2.10 | C21: Objectives / Goals | Q21: Objectives and goals should be concrete and measurable so that they are fit for reporting purposes
B22: 3.2.11 | C22: Statement of success | Q22: A statement of success is used to determine when the SOC is successful. Should be aligned with goals and objectives
C23: Completeness | L23: =VLOOKUP(SUM(_Output!D32:D42),_SUM_Completeness!A3:B14,2,FALSE) -> Incomplete | Q23: Use this outcome as a guideline to determine the score for 3.1
B24: 3.3 | C24: Is the SOC charter document regularly updated? | P24: =VLOOKUP(_Output!D43,_Guidance!B78:C83,2,FALSE) | Q24: Regularity should be matched to your own internal policy. At least yearly is recommended
B25: 3.4 | C25: Is the SOC charter document approved by the business / CISO? | P25: =VLOOKUP(_Output!D44,_Guidance!B84:C89,2,FALSE) | Q25: Approval from the relevant stakeholders will aid in business support for SOC operations
B26: 3.5 | C26: Are all stakeholders familiar with the SOC charter document contents? | P26: =VLOOKUP(_Output!D45,_Guidance!B90:C95,2,FALSE) | Q26: Making stakeholders aware of the contents helps in getting organizational support for security operations
B28: Comments and/or Remarks
B29: 3.6 | C29: Specify rationale for chosen values or any additional comments | L29: 3.1
L30: 3.3
L31: 3.4
L32: 3.5

Sheet Business - GOV
B1: Business
B3: 1. Business Drivers | G3: 5. Privacy & Policy
B4: 2. Customers
B5: 3. Charter
B6: 4. Governance
A9: 4 | B9: Governance | L9: Answer | N9: Importance | P9: Guidance | Q9: Remarks
B10: 4.1 | C10: Does the SOC have a governance process in place? | P10: =VLOOKUP(_Output!D49,_Guidance!B97:C102,2,FALSE) | Q10: A governance process is required to determine the way the SOC should be managed
B11: 4.2 | C11: Have all governance elements been identified? | P11: =VLOOKUP(_Output!D50,_Guidance!B103:C108,2,FALSE) | Q11: Possible governance elements can be found in under 4.3
B12: 4.3 | C12: Please specify identified governance elements
B13: 4.3.1 | C13: Business Alignment | Q13: Aligning SOC operations to business needs
B14: 4.3.2 | C14: Accountability | Q14: Note that this can be part of the SOC charter document. This does not automatically make it part of the governance process
B15: 4.3.3 | C15: Sponsorship | Q15: Can be part of stakeholder management
B16: 4.3.4 | C16: Mandate | Q16: Mandate for the SOC should be established so that the SOC can take action in crisis situations
B17: 4.3.5 | C17: Relationships & Third Party Management | Q17: Both management of internal and external relationships
B18: 4.3.6 | C18: Vendor Engagement | Q18: For example: active involvement of vendors in the creation of a vision and strategy for the SOC
B19: 4.3.7 | C19: Service Commitment | Q19: For example: service level agreements and IT controls
B20: 4.3.8 | C20: Project / Program Management | Q20: Project management for individual projects within the SOC / program management for larger transitions
B21: 4.3.9 | C21: Continual Improvement | Q21: Improvement of the SOC and of SOC management
B22: 4.3.10 | C22: Span of control / federation governance | Q22: Especially important for SOC setups where multiple SOCs exist within the same company
B23: 4.3.11 | C23: Outsourced service management | Q23: Especially important for hybrid SOC setups. When using outsourcing, SLAs and oversight should be in place
B24: 4.3.12 | C24: SOC KPIs & Metrics | Q24: These are discussed in more detail in the Process section regarding reporting
... B26: 4.3.14 | C26: Customer Engagement / Satisfaction | Q26: Are customers an integral part of your security operations? Is their satisfaction of SOC services every inquired about?
C27: Completeness | L27: =VLOOKUP(SUM(_Output!D52:D65),_SUM_Completeness!A17:B31,2,FALSE) -> Fully complete | Q27: Use this outcome as a guideline to determine the score for 4.2
B28: 4.4 | C28: Is cost management in place? | P28: =VLOOKUP(_Output!D66,_Guidance!B109:C114,2,FALSE) | Q28: Managing costs is required to justify budget allocation for the SOC and ensure continued service delivery in the future
B29: 4.5 | C29: Please specify cost management elements
B30: 4.5.1 | C30: People cost | Q30: Costs associated with employees. Should be managed to prove FTE requirements to stakeholders
B31: 4.5.2 | C31: Process cost | Q31: Cost associated with processes. Should be managed to ensure process elements can be delivered
B32: 4.5.3 | C32: Technology cost | Q32: Cost associated with technology. Should be managed to prove budget requirements for new technology or replacement
B33: 4.5.4 | C33: Services cost | Q33: Cost associated with service delivery. Especially important for managed service providers to ensure a healthy business model
B34: 4.5.5 | C34: Facility cost | Q34: Cost associated with facilities used by the SOC
B35: 4.5.6 | C35: Budget forecasting | Q35: Forecasting of required budget over time. Should be aligned with business needs; increased spending must be justified
B36: 4.5.7 | C36: Budget alignment | Q36: Alignment of budget with business requirements and drivers to ensure balanced spending on the SOC
B37: 4.5.8 | C37: Return on investment | Q37: Prove the return on investment to stakeholders to ensure continued budget allocation
C38: Completeness | L38: =VLOOKUP(SUM(_Output!D68:D75),_SUM_Completeness!A34:B42,2,FALSE) -> Incomplete | Q38: Use this outcome as a guideline to determine the score for 4.4
B39: 4.6 | C39: Are all governance elements formally documented? | P39: =VLOOKUP(_Output!D76,_Guidance!B115:C120,2,FALSE) | Q39: Formal documentation should be signed off and stored in a quality management system
B40: 4.7 | C40: Are SOC governance meetings regularly held? | P40: =VLOOKUP(_Output!D1077,_Guidance!B121:C126,2,FALSE) | Q40: SOC governance meetings at different levels (operational, tactical, strategic) should be formalised in Terms of Reference (ToR)
B41: 4.8 | C41: Is the governance process regularly reviewed? | P41: =VLOOKUP(_Output!D77,_Guidance!B127:C132,2,FALSE) | Q41: Regularity should be matched to your own internal policy. At least yearly is recommended
B42: 4.9 | C42: Is the governance process aligned with all stakeholders? | P42: =VLOOKUP(_Output!D78,_Guidance!B133:C138,2,FALSE) | Q42: Alignment will help the SOC obtain required mandate, budget and management support
B43: 4.10 | C43: Is the SOC regularly audited or subjected to external assessments? | P43: =VLOOKUP(_Output!D79,_Guidance!B139:C144,2,FALSE) | Q43: Frequency should be matched to your own internal policy. At least yearly is recommended
B44: 4.11 | C44: Is there an active cooperation with other SOCs (external)? | P44: =VLOOKUP(_Output!D984,_Guidance!B145:C150,2,FALSE) | Q44: Exchange of best practices, intelligence and actions on threats with other SOCs is vital for improving cyber defence
...

Sheet Business - PRV
B1: Business
B3: 1. Business Drivers | G3: 5. Privacy & Policy
B4: 2. Customers
B5: 3. Charter
B6: 4. Governance
A9: 5 | B9: Privacy & Policy | L9: Answer | N9: Importance | P9: Guidance | Q9: Remarks
B10: 5.1 | C10: Is there an information security policy in place that supports the SOC activities? | P10: =VLOOKUP(_Output!D986,_Guidance!B152:C157,2,FALSE) | Q10: A clear security policy that supports SOC operations provides guidance and helps to enforce mandate for the SOC in the organisation
B11: 5.2 | C11: Has a SOC policy been created? | P11: =VLOOKUP(_Output!D1078,_Guidance!B158:C163,2,FALSE) | Q11: A SOC policy is to outline the rules to which SOC personnel and SOC management needs to adhere
B12: 5.3 | C12: Please specify elements of the SOC policy
B13: 5.3.1 | C13: Code of conduct | Q13: How to behave in the SOC, mandatory and optional meetings, SOC culture, repercussions for non-compliance, etc.
B14: 5.3.2 | C14: Rules of engagement & responsibilities | Q14: What activities can and can not be performed as part of the job
B15: 5.3.3 | C15: Review frequency of documentation | Q15: What documentation is subjected to review and how often that documentation needs to be reviewed
B16: 5.3.4 | C16: SOC assessment frequency and type | Q16: How often the SOC is assessed and in what manner (self-assessment, audit, external assessment, etc.)
B17: 5.3.5 | C17: Knowledge exchange and maintenance | Q17: The means (meetings and platforms) for knowledge exchange and rules for maintenance of knowledge bases
B18: 5.3.6 | C18: Exercise frequency | Q18: Frequency and type (table top, cyber range, red team, etc.) of exercises in the SOC
B19: 5.3.7 | C19: Usage of TLP | Q19: Information exchange protocols. Especially important for collaborations outside the organisation
B20: 5.3.8 | C20: Working agreements | Q20: Agreements on length of meetings, length of agile sprints, transparency of completed work, etc.
C21: Completeness | L21: =VLOOKUP(SUM(_Output!D1080:D1087),_SUM_Completeness!A155:B163,2,FALSE) -> Incomplete | Q21: Use this outcome as a guideline to determine the score for 5.2
B22: 5.4 | C22: Is the SOC consulted in the creation and updates of operational security policy? | P22: =VLOOKUP(_Output!D988,_Guidance!B164:C169,2,FALSE) | Q22: Consulting the SOC in the creation of security policy will ensure that SOC activities are properly mentioned and enforceable
B23: 5.5 | C23: Is a reporting policy for security incidents in place? | P23: =VLOOKUP(_Output!D990,_Guidance!B170:C175,2,FALSE) | Q23: A reporting policy for security incidents will aid the SOC in identifying incidents and threats in the organization
B24: 5.6 | C24: Is a privacy policy regarding security monitoring of employees in place? | P24: =VLOOKUP(_Output!D83,_Guidance!B176:C181,2,FALSE) | Q24: A privacy policy should state that monitoring of employees is possible within acceptable limits
B25: 5.7 | C25: Does the SOC operate in compliance with all applicable privacy laws and regulations? | P25: =VLOOKUP(_Output!D84,_Guidance!B182:C187,2,FALSE) | Q25: Local laws and regulations as well as company policy may apply and should all be considered
B26: 5.8 | C26: Does the SOC cooperate with legal departments regarding privacy matters? | P26: =VLOOKUP(_Output!D87,_Guidance!B188:C193,2,FALSE) | Q26: Cooperation will ensure that the SOC is enabled to perform activities, rather than blocked
B27: 5.9 | C27: Are specific procedures in place for dealing with privacy related investigations? | P27: =VLOOKUP(_Output!D88,_Guidance!B194:C199,2,FALSE) | Q27: Privacy related issues require careful examination, especially those potentially leading to court cases
B28: 5.10 | C28: Is the SOC aware of all information that it processes and is subject to privacy regulations? | P28: =VLOOKUP(_Output!D89,_Guidance!B200:C205,2,FALSE) | Q28: Such information includes IP addresses, customer identifiers, user names, host names (for personally owned devices), etc.
B29: 5.11 | C29: Is a Privacy Impact Assessment (PIA) regularly conducted? | P29: =VLOOKUP(_Output!D90,_Guidance!B206:C211,2,FALSE) | Q29: Can be used to determine the impact of monitoring on privacy, and can help uncover potential violations
B31: Comments and/or Remarks
B32: 5.10 | C32: Specify rationale for chosen values or any additional comments | L32: 5.1
L33: 5.2
L34: 5.4
L35: 5.5
L36: 5.6
L37: 5.7
L38: 5.8
L39: 5.9

Sheet People - EMP
B1: People
B3: 1. Employees | G3: 5. Training & Education
B4: 2. Roles and Hierarchy
B5: 3. People Management
B6: 4. Knowledge Management
A9: 1 | B9: Employees | L9: Answer | N9: Importance | P9: Guidance | Q9: Remarks
B10: 1.1 | C10: How many FTE’s are in your SOC? | Q10: Include both internal and external FTE's
B11: 1.2 | C11: Do you use external employees / contractors in your SOC? | Q11: External employees can be hired experts to fill in vacant positions or perform project activities
B12: 1.2.1 | C12: If yes, specify the number of external FTE's | Q12: =IFERROR(CONCATENATE("Current ratio: ", ROUND(L12/L10*100, 2), "%"),"Current ratio: 0%") -> Current ratio: 0%
B13: 1.3 | C13: Does the current size of the SOC meet FTE requirements? | P13: =VLOOKUP(_Output!D98,_Guidance!B215:C220,2,FALSE) | Q13: i.e. is the SOC size sufficient to realize business goals?
B14: 1.4 | C14: Does the SOC meet requirements for internal to external employee FTE ratio? | P14: =VLOOKUP(_Output!D99,_Guidance!B221:C226,2,FALSE) | Q14: Note: requirements do not need to be explicit. Set importance to 'None' if you have no external employees.
B15: 1.5 | C15: Does the SOC meet requirements for internal to external employee skillset? | P15: =VLOOKUP(_Output!D100,_Guidance!B227:C232,2,FALSE) | Q15: i.e. Are there any crucial skills amongst external employees? Set importance to 'None' if you have no external employees
B16: 1.6 | C16: Are all positions filled? | P16: =VLOOKUP(_Output!D101,_Guidance!B233:C238,2,FALSE) | Q16: Unfilled positions may be due to deficiencies in the recruitment process
B17: 1.7 | C17: Do you have a recruitment process in place? | P17: =VLOOKUP(_Output!D102,_Guidance!B239:C244,2,FALSE) | Q17: A recruitment process is required to obtain new employees in a market where talent is scarce [1]
B18: 1.8 | C18: Do you have a talent acquisition process in place? | P18: =VLOOKUP(_Output!D103,_Guidance!B245:C250,2,FALSE) | Q18: Talent recruitment can be vital for SOC success, but talent retaining is equally important
B19: 1.9 | C19: Do you have specific KSAOs established for SOC personnel? | P19: =VLOOKUP(_Output!D994,_Guidance!B251:C256,2,FALSE) | Q19: Knowledge, Skills, Abilities and Other attributes (KSAOs) should be in place: technical, cognitive, social and character [2], [3]
B20: 1.10 | C20: Do you actively seek to create a psychologically safe environment for SOC personnel? | P20: =VLOOKUP(_Output!D995,_Guidance!B257:C262,2,FALSE) | Q20: A psychologically safe environment is an environment where everyone is able to speak their mind and feel valued
B22: Comments and/or Remarks
B23: 1.11 | C23: Specify rationale for chosen values or any additional comments | L23: 1.3
L24: 1.4
L25: 1.5
L26: 1.6
L27: 1.7
L28: 1.8
B29: [1] See the CSIRT social maturity handbook, pages 134-135 | L29: 1.9
B30: [2] See the CSIRT social maturity handbook, pages 41-42 | L30: 1.10
B31: [3] See the NIST NICE framework, specifically the Cyber Defense Analyst and Incident Responder roles:
C32: https://www.nist.gov/itl/applied-cybersecurity/nice/nice-framework-resource-center/nice-framework-supplemental-material

Sheet People - R&H
B1: People
B3: 1. Employees | G3: 5. Training & Education
B4: 2. Roles and Hierarchy
B5: 3. People Management
B6: 4. Knowledge Management
A9: 2 | B9: Roles and Hierarchy | L9: Answer | N9: Importance | P9: Guidance | Q9: Remarks
B10: 2.1 | C10: Do you formally differentiate roles within the SOC? | P10: =VLOOKUP(_Output!D107,_Guidance!B264:C269,2,FALSE) | Q10: Use the roles in 2.2 to determine if you have all roles required in the SOC
B11: 2.2 | C11: Which of the following roles are present in your SOC?
B12: 2.2.1 | C12: Security Analyst | Q12: Primarily responsible for triage and analysis of security alerts
B13: 2.2.2 | C13: Security / Systems Engineer | Q13: Primarily responsible for technical / functional maintenance of security systems
B14: 2.2.3 | C14: Forensic Analyst | Q14: Primarily responsible for in-depth analysis and security projects
B15: 2.2.4 | C15: Security Architect | Q15: Primarily responsible for technical architecture for security systems used within the SOC
B16: 2.2.5 | C16: Threat Intelligence Analyst | Q16: Primarily responsible for analysis of threat intelligence
B17: 2.2.6 | C17: Data Scientist | Q17: Primarily responsible for big data security analytics
B18: 2.2.7 | C18: SOC Manager | Q18: Primarily responsible for managing SOC services
B19: 2.2.8 | C19: Team Leader | Q19: Primarily responsible for leading a team of other, for example, analysts and engineers
B20: 2.2.9 | C20: Incident Handler | Q20: Primarily responsible for executing security incident management workflows
B21: 2.2.10 | C21: Incident Manager | Q21: Primarily responsible for ensuring correct and timely management and escalation of security incidents
B22: 2.2.11 | C22: Penetration Tester | Q22: Primarily responsible for testing applications and systems for security weaknesses
B23: 2.2.12 | C23: Detection engineer | Q23: Primarily responsible for creating and updating detection analytics
... B25: 2.2.14 | C25: Others, specify: | Q25: Specify any additional roles
B26: 2.3 | C26: Do you differentiate tiers within these roles? | P26: =VLOOKUP(_Output!D123,_Guidance!B270:C275,2,FALSE) | Q26: If you have no tiers, and you feel this is not a restriction, select importance 'None'
B27: 2.4 | C27: Are all roles sufficiently staffed? | P27: =VLOOKUP(_Output!D125,_Guidance!B276:C281,2,FALSE) | Q27: Consider the staffing levels (desired FTE count) as well as knowledge and experience for all roles
B28: 2.5 | C28: Is there a role-based hierarchy in your SOC? | P28: =VLOOKUP(_Output!D127,_Guidance!B282:C287,2,FALSE) | Q28: If you have no hierarchy, and you feel this is not a restriction, select importance 'None'
B29: 2.6 | C29: Have you formally documented all SOC roles? | P29: =VLOOKUP(_Output!D128,_Guidance!B288:C293,2,FALSE) | Q29: Possible documentation elements can be found in under 2.7
B30: 2.7 | C30: Please specify elements in the role documentation:
B31: 2.7.1 | C31: Role description | Q31: A formal description of the role
B32: 2.7.2 | C32: Role tasks | Q32: A description of tasks that are part of the role
B33: 2.7.3 | C33: Role responsibilities | Q33: The responsibilities of the role
B34: 2.7.4 | C34: Role expectations | Q34: This is an extension of responsibilities. Example expectation: take a pro-active leading role in case of security incidents
B35: 2.7.5 | C35: Required technical skills | Q35: e.g. experience with specific technologies or products
B36: 2.7.6 | C36: Required soft skills | Q36: e.g. communication skills, presentation skills
B37: 2.7.7 | C37: Required educational level | Q37: e.g. university college, university
B38: 2.7.8 | C38: Required or preferred certifications | Q38: e.g. technical security certifications or security management certifications
C39: Completeness | L39: =VLOOKUP(SUM(_Output!D132:D139),_SUM_Completeness!A58:B66,2,FALSE) -> Incomplete | Q39: Use this outcome as a guideline to determine the score for 2.6
B40: 2.8 | C40: Are responsibilities for each role understood? | P40: =VLOOKUP(_Output!D140,_Guidance!B294:C299,2,FALSE) | Q40: Responsibilities for each role should be clearly understood by all SOC personnel
B41: 2.9 | C41: Have you documented career progression requirements for each of these roles? | P41: =VLOOKUP(_Output!D143,_Guidance!B300:C305,2,FALSE) | Q41: Career progression for roles can be documented through training, certification, experience and soft skills requirements
B42: 2.10 | C42: Do you regularly revise or update the role descriptions? | P42: =VLOOKUP(_Output!D144,_Guidance!B306:C311,2,FALSE) | Q42: To revise is to review and verify whether to documentation is still correct or requires an update
B44: Comments and/or Remarks
B45: 2.11 | C45: Specify rationale for chosen values or any additional comments | L45: 2.1
...

Sheet People - PEM
B1: People
B3: 1. Employees | G3: 5. Training & Education
B4: 2. Roles and Hierarchy
B5: 3. People Management
B6: 4. Knowledge Management
A9: 3 | B9: People Management | L9: Answer | N9: Importance | P9: Guidance | Q9: Remarks
B10: 3.1 | C10: Do you have a job rotation plan in place? | P10: =VLOOKUP(_Output!D148,_Guidance!B314:C319,2,FALSE) | Q10: Job rotation can be used to train employees in a variety of tasks and avoid too much routine
B11: 3.2 | C11: Do you have a career progression process in place? | P11: =VLOOKUP(_Output!D149,_Guidance!B320:C325,2,FALSE) | Q11: Career development, promotion, etc.
B12: 3.3 | C12: Do you have a talent management process in place? | P12: =VLOOKUP(_Output!D150,_Guidance!B326:C331,2,FALSE) | Q12: Talent should be adequately managed to retain such staff and fully develop their potential.
B13: 3.4 | C13: Do you have team diversity goals? | P13: =VLOOKUP(_Output!D151,_Guidance!B332:C337,2,FALSE) | Q13: e.g. background diversity, ethnic diversity, gender diversity, etc.
B14: 3.5 | C14: Have you established team goals? | P14: =VLOOKUP(_Output!D996,_Guidance!B338:C343,2,FALSE) | Q14: Team goals help to bring focus to the team and monitor progress
B15: 3.6 | C15: Do you document and track individual team member goals? | P15: =VLOOKUP(_Output!D997,_Guidance!B344:C349,2,FALSE) | Q15: Individual team member goals should be set to help grow the employee to full potential
B16: 3.7 | C16: Do you periodically evaluate SOC employees? | P16: =VLOOKUP(_Output!D152,_Guidance!B350:C355,2,FALSE) | Q16: Can also be included in the regular organization evaluation process
B17: 3.8 | C17: Do you have a 'new hire' process in place? | P17: =VLOOKUP(_Output!D153,_Guidance!B356:C361,2,FALSE) | Q17: i.e. a defined process to quickly let new employees find their place and perform well in the SOC
B18: 3.9 | C18: Are all SOC employees subjected to screening? | P18: =VLOOKUP(_Output!D154,_Guidance!B362:C367,2,FALSE) | Q18: Personnel screening is performed to avoid infiltration or misbehavior by SOC employees
B19: 3.10 | C19: Do you measure employee satisfaction for improving the SOC? | P19: =VLOOKUP(_Output!D155,_Guidance!B368:C373,2,FALSE) | Q19: Employee satisfaction should be taken seriously as lack of satisfaction may lead to key personnel leaving
B20: 3.11 | C20: Are there regular 1-on-1 meetings between the SOC manager and the employees? | P20: =VLOOKUP(_Output!D156,_Guidance!B374:C379,2,FALSE) | Q20: Such informal 1-on-1 conversations are used to coach employees and help the SOC manager gain insight in personal challenges
B21: 3.12 | C21: Do you perform regular teambuilding exercises? | P21: =VLOOKUP(_Output!D157,_Guidance!B380:C385,2,FALSE) | Q21: Teambuilding exercises are used to promote collaboration between individuals in the team and to raise team spirit
B22: 3.13 | C22: Do you perform regular teambuilding exercises with other teams relevant to the SOC? | P22: =VLOOKUP(_Output!D998,_Guidance!B386:C391,2,FALSE) | Q22: In multi-team systems (MTS), the SOC collaborates with other teams. Use cross-team teambuilding to maximize performance
B23: 3.14 | C23: Do you periodically evaluate team performance? | P23: =VLOOKUP(_Output!D999,_Guidance!B392:C397,2,FALSE) | Q23: Besides individual performance, team performance and dynamics are also important to measure and improve on
B25: Comments and/or Remarks
B26: 3.15 | C26: Specify rationale for chosen values or any additional comments | L26: 3.1
L27: 3.2
L28: 3.3
L29: 3.4
L30: 3.5
L31: 3.6
L32: 3.7
L33: 3.8
L34: 3.9
L35: 3.10
L36: 3.11
L37: 3.12
L38: 3.13
L39: 3.14

Sheet People - KNM
B1: People
B3: 1. Employees | G3: 5. Training & Education
B4: 2. Roles and Hierarchy
B5: 3. People Management
B6: 4. Knowledge Management
A9: 4 | B9: Knowledge Management | L9: Answer | N9: Importance | P9: Guidance | Q9: Remarks
B10: 4.1 | C10: Do you have a formal knowledge management process in place? | P10: =VLOOKUP(_Output!D161,_Guidance!B400:C405,2,FALSE) | Q10: Formal knowledge management helps to optimize knowledge creation and distribution
B11: 4.2 | C11: Do you have a skill matrix in place? | P11: =VLOOKUP(_Output!D1091,_Guidance!B406:C411,2,FALSE) | Q11: A matrix may consist of: SOC skills, SOC employees and skill levels (novice, intermediate, expert)
B12: 4.3 | C12: Please specify elements of the skilll matrix:
B13: 4.3.1 | C13: All SOC employees | Q13: The skill matrix should cover all SOC employees, both internal and external
B14: 4.3.2 | C14: Hard skills | Q14: e.g. ability to effectively use analysis tools
B15: 4.3.3 | C15: Soft skills | Q15: e.g. communication skills
B16: 4.3.4 | C16: Skill levels (novice, intermediate, expert) | Q16: Determining and documenting skill levels helps to identify areas where limited expertise is available
C17: Completeness | L17: =VLOOKUP(SUM(_Output!D1092:D1095),_SUM_Completeness!A195:B199,2,FALSE) -> Incomplete | Q17: Use this outcome as a guideline to determine the score for 4.2
B18: 4.4 | C18: Is the skill matrix actively used for team and personal improvement? | P18: =VLOOKUP(_Output!D1096,_Guidance!B412:C417,2,FALSE) | Q18: Personal improvement is essential, team improvement requires insight in team dynamics and skill distribution
B19: 4.5 | C19: Do you have a knowledge matrix in place? | P19: =VLOOKUP(_Output!D1097,_Guidance!B418:C423,2,FALSE)
B20: 4.6 | C20: Please specify elements of the knowledge matrix:
B21: 4.6.1 | C21: All SOC employees | Q21: The knowledge matrix should cover all SOC employees, both internal and external
B22: 4.6.2 | C22: All relevant knowledge areas | Q22: Knowledge for service delivery: technical (i.e. support), functional (i.e. configuration) and foundational (e.g. networking, encryption)
B23: 4.6.3 | C23: Knowledge levels (novice, intermediate, expert) | Q23: Determining and documenting knowledge levels helps to identify areas where limited expertise is available
C24: Completeness | L24: =VLOOKUP(SUM(_Output!D1098:D1100),_SUM_Completeness!A202:B205,2,FALSE) -> Incomplete | Q24: Use this outcome as a guideline to determine the score for 4.5
B25: 4.7 | C25: Is the knowledge matrix acively used to determine training and education needs? | P25: =VLOOKUP(_Output!D1101,_Guidance!B424:C429,2,FALSE) | Q25: The matrix should be used as a means to identify and resolve knowledge gaps
B26: 4.8 | C26: Have you documented SOC team member abilities? | P26: =VLOOKUP(_Output!D1000,_Guidance!B430:C435,2,FALSE) | Q26: Besides knowledge and skills, team member abilities are also important to document
