Workbook
Name _GoBack: '4-POST INCIDENT ACTIVITY (PIA)'!#REF!
Name Access_Control__PR.AC___Access_to_assets_and_associated_facilities_is_limited_to_authorized_users__processes__or_devices__and_to_authorized_activities_and_transactions.: 'CSF Core'!$B$85
Name Access_Control__PR.AC__Total: '2-DETECTION & ANALYSIS (DA)'!$A$6
Name Analysis__RS.AN__Total: '4-POST INCIDENT ACTIVITY (PIA)'!$A$14
Name Anomalies_and_Events__DE.AE__Total: '3-C,E & R (CER)'!$A$6
Name Asset_Management__ID.AM__Total: '1-PREPARATION (PR)'!$A$6
Name Awareness_and_Training__PR.AT__Total: '2-DETECTION & ANALYSIS (DA)'!$A$15
Name Business_Environment__ID.BE__Total: '1-PREPARATION (PR)'!$A$13
Name Communications__RC.CO___Restoration_activities_are_coordinated_with_internal_and_external_parties__such_as_coordinating_centers__Internet_Service_Providers__owners_of_attacking_systems__victims__other_CSIRTs__and_vendors.: 'CSF Core'!$B$356
Name Communications__RC.CO__Total: #REF!
Name Communications__RS.CO__Total: '4-POST INCIDENT ACTIVITY (PIA)'!$A$9
Name Data_Security__PR.DS__Total: '2-DETECTION & ANALYSIS (DA)'!$A$18
Name DE.AE_1__A_baseline_of_network_operations_and_expected_data_flows_for_users_and_systems_is_established_and_managed: 'CSF Core'!$C$240
Name DE.AE_2__Detected_events_are_analyzed_to_understand_attack_targets_and_methods: 'CSF Core'!$C$243
Name DE.AE_3__Event_data_are_aggregated_and_correlated_from_multiple_sources_and_sensors: 'CSF Core'!$C$247
Name DE.AE_4__Impact_of_events_is_determined: 'CSF Core'!$C$249
Name DE.AE_5__Incident_alert_thresholds_are_established: 'CSF Core'!$C$251
Name DE.CM_1__The_network_is_monitored_to_detect_potential_cybersecurity_events: 'CSF Core'!$C$254
Name DE.CM_2__The_physical_environment_is_monitored_to_detect_potential_cybersecurity_events: 'CSF Core'!$C$258
Name DE.CM_3__Personnel_activity_is_monitored_to_detect_potential_cybersecurity_events: 'CSF Core'!$C$260
Name DE.CM_4__Malicious_code_is_detected: 'CSF Core'!$C$263
Name DE.CM_5__Unauthorized_mobile_code_is_detected: 'CSF Core'!$C$269
Name DE.CM_6__External_service_provider_activity_is_monitored_to_detect_potential_cybersecurity_events: 'CSF Core'!$C$272
Name DE.CM_7__Monitoring_for_unauthorized_personnel__connections__devices__and_software_is_performed: 'CSF Core'!$C$275
Name DE.CM_8__Vulnerability_scans_are_performed: 'CSF Core'!$C$276
Name DE.DP_1__Roles_and_responsibilities_for_detection_are_well_defined_to_ensure_accountability: 'CSF Core'!$C$280
Name DE.DP_2__Detection_activities_comply_with_all_applicable_requirements: 'CSF Core'!$C$285
Name DE.DP_3__Detection_processes_are_tested: 'CSF Core'!$C$288
Name DE.DP_4__Event_detection_information_is_communicated_to_appropriate_parties: 'CSF Core'!$C$293
Name DE.DP_5__Detection_processes_are_continuously_improved: 'CSF Core'!$C$298
Name Detection_Processes__DE.DP__Total: '3-C,E & R (CER)'!$A$12
Name Governance__ID.GV__Total: '1-PREPARATION (PR)'!#REF!
Name ID.BE_3: 'CSF Core'!$C$36
Name ID.BE_3__Priorities_for_organizational_mission__objectives__and_activities_are_established_and_communicated: 'CSF Core'!$C$36
Name ID.BE_4__Dependencies_and_critical_functions_for_delivery_of_critical_services_are_established: 'CSF Core'!$C$39
Name ID.BE_5__Resilience_requirements_to_support_delivery_of_critical_services_are_established: 'CSF Core'!$C$41
Name ID.GV_1__Organizational_information_security_policy_is_established: 'CSF Core'!$C$44
Name ID.GV_2__Information_security_roles___responsibilities_are_coordinated_and_aligned_with_internal_roles_and_external_partners: 'CSF Core'!$C$48
Name ID.GV_3__Legal_and_regulatory_requirements_regarding_cybersecurity__including_privacy_and_civil_liberties_obligations__are_understood_and_managed: 'CSF Core'!$C$52
Name ID.GV_4__Governance_and_risk_management_processes_address_cybersecurity_risks: 'CSF Core'!$C$56
Name ID.RA_1__Asset_vulnerabilities_are_identified_and_documented: 'CSF Core'!$C$59
Name ID.RA_2__Threat_and_vulnerability_information_is_received_from_information_sharing_forums_and_sources: 'CSF Core'!$C$64
Name ID.RA_3__Threats__both_internal_and_external__are_identified_and_documented: 'CSF Core'!$C$67
Name ID.RA_4__Potential_business_impacts_and_likelihoods_are_identified: 'CSF Core'!$C$70
Name ID.RA_5__Threats__vulnerabilities__likelihoods__and_impacts_are_used_to_determine_risk: 'CSF Core'!$C$73
Name ID.RA_6__Risk_responses_are_identified_and_prioritized: 'CSF Core'!$C$76
Name ID.RM_1__Risk_management_processes_are_established__managed__and_agreed_to_by_organizational_stakeholders: 'CSF Core'!$C$78
Name ID.RM_2__Organizational_risk_tolerance_is_determined_and_clearly_expressed: 'CSF Core'!$C$81
Name ID.RM_3__The_organization’s_determination_of_risk_tolerance_is_informed_by_its_role_in_critical_infrastructure_and_sector_specific_risk_analysis: 'CSF Core'!$C$84
Name Improvements__RC.IM__Total: #REF!
Name Improvements__RS.IM__Total: '4-POST INCIDENT ACTIVITY (PIA)'!#REF!
Name Information_Protection_Processes_and_Procedures__PR.IP__Total: '2-DETECTION & ANALYSIS (DA)'!$A$29
Name Maintenance__PR.MA__Total: '2-DETECTION & ANALYSIS (DA)'!$A$40
Name Mitigation__RS.MI__Total: '4-POST INCIDENT ACTIVITY (PIA)'!#REF!
Name PR.AC_1__Identities_and_credentials_are_managed_for_authorized_devices_and_users: 'CSF Core'!$C$85
Name PR.AC_2__Physical_access_to_assets_is_managed_and_protected: 'CSF Core'!$C$91
Name PR.AC_3__Remote_access_is_managed: 'CSF Core'!$C$95
Name PR.AC_4__Access_permissions_are_managed__incorporating_the_principles_of_least_privilege_and_separation_of_duties: 'CSF Core'!$C$100
Name PR.AC_5__Network_integrity_is_protected__incorporating_network_segregation_where_appropriate: 'CSF Core'!$C$105
Name PR.AT_1__All_users_are_informed_and_trained: 'CSF Core'!$C$109

Sheet Introduction
A26: Select the appropriate rating for each question

Sheet CSF Tiers
A2: NIST Cyber Security Framework Implementation Tiers
A3: Metric | C3: COBIT 5
A4: Level 0 - Does not exist | B4: 0 | C4: The process is not implemented or fails to achieve its purpose.
A5: Level 1 - Partial | B5: 1 | C5: • Risk Management Process – Organizational cybersecurity risk management practices are not formalized, and risk is managed in an ad hoc and sometimes reactive manner. Prioritization of cybersecurity activities may not be directly informed by organizational risk objectives, the threat environment, or business/mission requirements. • Integrated Risk Management Program – There is limited awareness of cybersecurity risk at the organizational level and an organization-wide approach to managing cybersecurity risk has not been established. The organization implements cybersecurity risk management on an irregular, case-by-case basis due to varied experience or information gained from outside sources. The organization may not have processes that enable cybersecurity information to be shared within the organization. • External Participation – An organization may not have the processes in place to participate in coordination or collaboration with other entities.
A6: Level 2 - Risk Informed | B6: 2 | C6: • Risk Management Process – Risk management practices are approved by management but may not be established as organizational-wide policy. Prioritization of cybersecurity activities is directly informed by organizational risk objectives, the threat environment, or business/mission requirements. • Integrated Risk Management Program – There is an awareness of cybersecurity risk at the organizational level but an organization-wide approach to managing cybersecurity risk has not been established. Risk-informed, management-approved processes and procedures are defined and implemented, and staff has adequate resources to perform their cybersecurity duties. Cybersecurity information is shared within the organization on an informal basis. • External Participation – The organization knows its role in the larger ecosystem, but has not formalized its capabilities to interact and share information externally.
A7: Level 3 - Repeatable | B7: 3 | C7: • Risk Management Process – The organization’s risk management practices are formally approved and expressed as policy. Organizational cybersecurity practices are regularly updated based on the application of risk management processes to changes in business/mission requirements and a changing threat and technology landscape. • Integrated Risk Management Program – There is an organization-wide approach to manage cybersecurity risk. Risk-informed policies, processes, and procedures are defined, implemented as intended, and reviewed. Consistent methods are in place to respond effectively to changes in risk. Personnel possess the knowledge and skills to perform their appointed roles and responsibilities. • External Participation – The organization understands its dependencies and partners and receives information from these partners that enables collaboration and risk-based management decisions within the organization in response to events.
A8: Level 4 - Adaptive | B8: 4 | C8: • Risk Management Process – The organization adapts its cybersecurity practices based on lessons learned and predictive indicators derived from previous and current cybersecurity activities. Through a process of continuous improvement incorporating advanced cybersecurity technologies and practices, the organization actively adapts to a changing cybersecurity landscape and responds to evolving and sophisticated threats in a timely manner. • Integrated Risk Management Program – There is an organization-wide approach to managing cybersecurity risk that uses risk-informed policies, processes, and procedures to address potential cybersecurity events. Cybersecurity risk management is part of the organizational culture and evolves from an awareness of previous activities, information shared by other sources, and continuous awareness of activities on their systems and networks. • External Participation – The organization manages risk and actively shares information with partners to ensure that accurate, current information is being distributed and consumed to improve cybersecurity before a cybersecurity event occurs.

Sheet SUMMARY-All Categories
B2: Client Cyber Security Assessment - SUMMARY SCORES
B4: Cyber Security Assessment Category | C4: Current Program | D4: Target Program | E4: Percentage Met | F4: Perfect Program
A5: 1 | B5: PREPARATION (PR) | C5: ='1-PREPARATION (PR)'!E5 -> 2.65 | D5: ='1-PREPARATION (PR)'!F5 -> 4 | E5: ='1-PREPARATION (PR)'!G5 -> 0.6625 | F5: 4
A6: 2 | B6: DETECTION & ANALYSIS (DA) | C6: ='2-DETECTION & ANALYSIS (DA)'!E5 -> 2.1163961 | D6: ='2-DETECTION & ANALYSIS (DA)'!F5 -> 4 | E6: ='2-DETECTION & ANALYSIS (DA)'!G5 -> 0.52909903 | F6: 4
A7: 3 | B7: CONTAINMENT, ERADICATOIN & RECOVERY (CER) | C7: ='3-C,E & R (CER)'!E5 -> 2.25 | D7: ='3-C,E & R (CER)'!F5 -> 4 | E7: ='3-C,E & R (CER)'!G5 -> 0.5625 | F7: 4
A8: 4 | B8: POST INCIDENT ACTIVITY (PIA) | C8: ='4-POST INCIDENT ACTIVITY (PIA)'!E5 -> 2.25 | D8: ='4-POST INCIDENT ACTIVITY (PIA)'!F5 -> 4 | E8: ='4-POST INCIDENT ACTIVITY (PIA)'!G5 -> 0.5625 | F8: 4
F11: Cyber Security Tiers
F12: Description | G12: Value
F13: Does Not Exist = 0 | G13: 0
F14: Performed=1 | G14: 1
F15: Managed=2 | G15: 2
F16: Established=3 | G16: 3
F17: Predictable=4 | G17: 4
B27: Cyber Security Assessment Controls | C27: Current Program | D27: Percentage Met
B28: Preparing to Handle Incident Total | C28: ='1-PREPARATION (PR)'!E6 -> 2.5 | D28: ='1-PREPARATION (PR)'!G6 -> 0.625
B29: Preventing Incidents Total | C29: ='1-PREPARATION (PR)'!E13 -> 2.8 | D29: ='1-PREPARATION (PR)'!G13 -> 0.7
B30: Attack Vectors | C30: ='2-DETECTION & ANALYSIS (DA)'!E6 -> 1.875 | D30: ='2-DETECTION & ANALYSIS (DA)'!G6 -> 0.46875
B31: Signs of an incident | C31: ='2-DETECTION & ANALYSIS (DA)'!E15 -> 2 | D31: ='2-DETECTION & ANALYSIS (DA)'!G15 -> 0.5
B32: Sources of precursors and indicators | C32: ='2-DETECTION & ANALYSIS (DA)'!E18 -> 1.7142857 | D32: ='2-DETECTION & ANALYSIS (DA)'!G18 -> 0.42857143
B33: Incident Analysis | C33: ='2-DETECTION & ANALYSIS (DA)'!E6 -> 1.875 | D33: ='2-DETECTION & ANALYSIS (DA)'!G6 -> 0.46875
B34: Incident documentation | C34: ='2-DETECTION & ANALYSIS (DA)'!E15 -> 2 | D34: ='2-DETECTION & ANALYSIS (DA)'!G15 -> 0.5
B35: Incident prioritization | C35: ='2-DETECTION & ANALYSIS (DA)'!E18 -> 1.7142857 | D35: ='2-DETECTION & ANALYSIS (DA)'!G18 -> 0.42857143
B36: Incident Notification | C36: ='2-DETECTION & ANALYSIS (DA)'!E29 -> 2.2 | D36: ='2-DETECTION & ANALYSIS (DA)'!G29 -> 0.55
B37: Choosing a Containment Strategy Total | C37: ='2-DETECTION & ANALYSIS (DA)'!E40 -> 2.9090909 | D37: ='2-DETECTION & ANALYSIS (DA)'!G40 -> 0.72727273
B38: Evidence gathering and handling Total | C38: ='2-DETECTION & ANALYSIS (DA)'!E52 -> 2 | D38: ='2-DETECTION & ANALYSIS (DA)'!G52 -> 0.5
B39: Identifying the attacking hosts Total | C39: ='3-C,E & R (CER)'!E6 -> 3.5 | D39: ='3-C,E & R (CER)'!G6 -> 0.875
B40: Eradication and Recovery | C40: ='3-C,E & R (CER)'!E9 -> 1 | D40: ='3-C,E & R (CER)'!G9 -> 0.25
B41: Lessons Learned Total | C41: ='3-C,E & R (CER)'!E12 -> 2.5 | D41: ='3-C,E & R (CER)'!G12 -> 0.625
B42: Using Collected Incident Data Total | C42: ='4-POST INCIDENT ACTIVITY (PIA)'!E6 -> 2 | D42: ='4-POST INCIDENT ACTIVITY (PIA)'!G6 -> 0.5
B43: Evidence Retention Total | C43: ='4-POST INCIDENT ACTIVITY (PIA)'!E9 -> 1.75 | D43: ='4-POST INCIDENT ACTIVITY (PIA)'!G9 -> 0.4375
B50: Cyber Security Assessment Controls | C50: Q1 2022 | D50: Deloitte SOC Impact | E50: H1 2023 | F50: H2 2023 | G50: Max Score | H50: Total Controls | I50: Controls where SOC has impact
B51: Preparing to Handle Incident Total | C51: 2.5 | D51: Medium | E51: 2.75 | F51: 3 | G51: 2.8 | H51: 6 | I51: 3
B52: Preventing Incidents Total | C52: 2.8 | D52: Low | E52: 2.9 | F52: 3 | G52: 3.1 | H52: 5 | I52: 1
B53: Attack Vectors | C53: 1.875 | D53: High | E53: 2.5 | F53: 3 | G53: 2.82 | H53: 8 | I53: 4
B54: Signs of an incident | C54: 2 | D54: High | E54: 2.5 | F54: 3 | G54: 3.7 | H54: 2 | I54: 2
B55: Sources of precursors and indicators | C55: 1.7142857 | D55: High | E55: 2.5 | F55: 3 | G55: 3 | H55: 10 | I55: 7
B56: Incident Analysis | C56: 1.875 | D56: High | E56: 2.5 | F56: 3 | G56: 3.7 | H56: 10 | I56: 10
B57: Incident documentation | C57: 2 | D57: High | E57: 2.5 | F57: 3 | G57: 3.7 | H57: 11 | I57: 11
B58: Incident prioritization | C58: 1.7142857 | D58: High | E58: 2.5 | F58: 3 | G58: 3.7 | H58: 1 | I58: 1
B59: Incident Notification | C59: 2.2 | D59: High | E59: 2.5 | F59: 3 | G59: 3.7 | H59: 1 | I59: 1
...

Sheet 1-PREPARATION (PR)
A2: 1 - Preparation (PR)
A3: Review the following categories in order to assess the cyber security program. L0 (Does Not Exist), L1 (Partial), L2 (Risk Informed), L3 (Repeatable), L4 (Adaptive)
A4: Category | B4: Questionnaire | C4: Client's Summary | D4: Stakeholders Interviewed (Name, Title) | E4: Current Process Score | F4: Target Process Score | G4: % of Current / Target
A5: Preparation (PR) Grand Total | E5: =AVERAGE(E6,E13) -> 2.65 | F5: 4 | G5: =E5/F5 -> 0.6625
A6: Preparing to Handle Incident Total | E6: =AVERAGE(E7:E12) -> 2.5 | F6: 4 | G6: =E6/F6 -> 0.625
B7: Physical devices and systems within the organization are inventoried | E7: 2 | F7: 4 | G7: =E7/F7 -> 0.5 | H7: 2
B8: Software platforms and applications within the organization are inventoried | E8: 2 | F8: 4 | G8: =E8/F8 -> 0.5 | H8: 2
B9: Incident Handler communications and facilites: Contact information On-call information Incident reporting mechanism Issue tracking system Encryption Software War room Secure storage facilities | E9: 3 | F9: 4 | G9: =E9/F9 -> 0.75 | H9: 3.75
B10: Incident Analysis hardware and software: Digital Forensics Workstation and backup devices. Jump Kits(workstations/laptops with all the incident analysis hardware software) | E10: 3 | F10: 4 | G10: =E10/F10 -> 0.75 | H10: 3.75
B11: Inciden Analysis resources: Port Lists Documentation for security products Network Diagrams and list of critical assets Current baselines(All the exiting incident related baselines including incident clasification) | E11: 2 | F11: 4 | G11: =E11/F11 -> 0.5 | H11: 2
B12: Incident Mitigation Software: Access to image | E12: 3 | F12: 4 | G12: =E12/F12 -> 0.75 | H12: 3.75
A13: Preventing Incidents Total | E13: =AVERAGE(E14:E18) -> 2.8 | F13: 4 | G13: =E13/F13 -> 0.7
B14: Risk Assessment | E14: 3 | F14: 4 | G14: =E14/F14 -> 0.75 | H14: 3
B15: Host Security (e.g. hardening, patching, RBAC etc) | E15: 3 | F15: 4 | G15: =E15/F15 -> 0.75 | H15: 3
B16: Network Security (e.g. firewall policies, VPNs, NACs etc) | E16: 3 | F16: 4 | G16: =E16/F16 -> 0.75 | H16: 3
B17: Malware prevention | E17: 2 | F17: 4 | G17: =E17/F17 -> 0.5 | H17: 3.75
B18: User awareness and training | E18: 3 | F18: 4 | G18: =E18/F18 -> 0.75 | H18: 3

Sheet 2-DETECTION & ANALYSIS (DA)
A2: 2 - DETECTION AND ANALYSIS (DA)
A3: Review the following categories in order to assess the cyber security program. L0 (Does Not Exist), L1 (Partial), L2 (Risk Informed), L3 (Repeatable), L4 (Adaptive)
A4: Category | B4: Questionnaire | C4: Client's Summary | D4: Stakeholders Interviewed (Name, Title) | E4: Current Process Score | F4: Target Process Score | G4: % of Current / Target
A5: DETECTION AND ANALYSIS (DA) Grand Total | E5: =AVERAGE(E6,E15,E18,E29,E40,E52) -> 2.1163961 | F5: 4 | G5: =E5/F5 -> 0.52909903
A6: Attack Vectors | E6: =AVERAGE(E7:E14) -> 1.875 | F6: 4 | G6: =E6/F6 -> 0.46875
B7: External/Removable Media | E7: 2 | F7: 4 | G7: =E7/F7 -> 0.5 | H7: 2
B8: Attrition(e.g. ddos, bruteforce) | E8: 2 | F8: 4 | G8: =E8/F8 -> 0.5 | H8: 2
B9: Web(e.g xss, sql injection etc) | E9: 3 | F9: 4 | G9: =E9/F9 -> 0.75 | H9: 3.75
B10: Email(e.g Phishing, malware) | E10: 2 | F10: 4 | G10: =E10/F10 -> 0.5 | H10: 3.75
B11: Impersonation(e.g spoofing, MITM, rogue dns or dhcp) | E11: 2 | F11: 4 | G11: =E11/F11 -> 0.5 | H11: 3.75
B12: Improper usage(e.g. org policy breach) | E12: 2 | F12: 4 | G12: =E12/F12 -> 0.5 | H12: 2
B13: Loss or Theft of equipment | E13: 2 | F13: 4 | G13: =E13/F13 -> 0.5 | H13: 2
B14: others( if incident can not be categorised) | E14: 0 | F14: 4 | G14: =E14/F14 -> 0 | H14: 3.75
A15: Signs of an incident | E15: =AVERAGE(E16:E17) -> 2 | F15: 4 | G15: =E15/F15 -> 0.5
B16: Focus on precursors(e.g vulnerability data, announcement of a new targeted exploit) | E16: 2 | F16: 4 | G16: =E16/F16 -> 0.5 | H16: 3.75
B17: Focus on indicators(e.g. Signatures detected in AV, IDS, SIEM use cases) | E17: 2 | F17: 4 | G17: =E17/F17 -> 0.5 | H17: 3.75
A18: Sources of precursors and indicators | E18: =AVERAGE(E19:E25) -> 1.7142857 | F18: 4 | G18: =E18/F18 -> 0.42857143
B19: IDPSs | E19: 2 | F19: 4 | G19: =E19/F19 -> 0.5 | H19: 2
B20: SIEM | E20: 2 | F20: 4 | G20: =E20/F20 -> 0.5 | H20: 3.75
B21: Antivirus and Antispam Softwares | E21: 2 | F21: 4 | G21: =E21/F21 -> 0.5 | H21: 2
B22: File integrity checking softwares | E22: 0 | F22: 4 | G22: =E22/F22 -> 0 | H22: 0
B23: Third party monitoring services(e.g. fraud detection) | E23: 1 | F23: 4 | G23: =E23/F23 -> 0.25 | H23: 3.75
B24: Logs from Operating systems, Services and applications, Network Devices | E24: 3 | F24: 4 | G24: =E24/F24 -> 0.75 | H24: 3.75
B25: Flows from the network | E25: 2 | F25: 4 | G25: =E25/F25 -> 0.5 | H25: 3.75
B26: Publicly available information like Vulnerabilities and exploits | E26: 2 | F26: 4 | G26: =E26/F26 -> 0.5 | H26: 3.75
B27: Incident reporting from people within the organization | E27: 4 | F27: 4 | G27: =E27/F27 -> 1 | H27: 3.75
B28: Incident reporting from people outside the organization | E28: 2 | F28: 4 | G28: =E28/F28 -> 0.5 | H28: 3.75
A29: Incident Analysis | E29: =AVERAGE(E30:E39) -> 2.2 | F29: 4 | G29: =E29/F29 -> 0.55
B30: Network and systems profiling | E30: 2 | F30: 4 | G30: =E30/F30 -> 0.5
B31: Understanding of normal behaviors | E31: 1 | F31: 4 | G31: =E31/F31 -> 0.25
B32: Creation of a log retention policy | E32: 2 | F32: 4 | G32: =E32/F32 -> 0.5
B33: Performing event correlation | E33: 2 | F33: 4 | G33: =E33/F33 -> 0.5
B34: Keeping a check on all hosts clock sync | E34: 3 | F34: 4 | G34: =E34/F34 -> 0.75
B35: Maintaining and usage of KB of information | E35: 3 | F35: 4 | G35: =E35/F35 -> 0.75
B36: Usage of internet for research on threats and vunerabilities | E36: 2 | F36: 4 | G36: =E36/F36 -> 0.5
B37: Usage of network flows to collect additional data | E37: 1 | F37: 4 | G37: =E37/F37 -> 0.25
B38: Efficient data filtering for analysis | E38: 3 | F38: 4 | G38: =E38/F38 -> 0.75
B39: Seeking help from others(e.g. CSIRT, outside IR expertise) | E39: 3 | F39: 4 | G39: =E39/F39 -> 0.75
A40: Incident documentation | E40: =AVERAGE(E41:E51) -> 2.9090909 | F40: 4 | G40: =E40/F40 -> 0.72727273
B41: The current status of the incident (new, in progress, forwarded for investigation, resolved, etc.) | E41: 3 | F41: 4 | G41: =E41/F41 -> 0.75
...

Sheet 3-C,E & R (CER)
A2: 3 - Containment, Eradication & Recovery (CER)
A3: Review the following categories in order to assess the cyber security program. L0 (Does Not Exist), L1 (Partial), L2 (Risk Informed), L3 (Repeatable), L4 (Adaptive)
A4: Category | B4: Questionnaire | C4: Client's Summary | D4: Stakeholders Interviewed (Name, Title) | E4: Current Process Score | F4: Target Process Score | G4: % of Current / Target
A5: Containment, Eradication & Recovery (CER) Grand Total | E5: =AVERAGE(E6,E9) -> 2.25 | F5: 4 | G5: =E5/F5 -> 0.5625
A6: Choosing a Containment Strategy Total | E6: =AVERAGE(E7:E8) -> 3.5 | F6: 4 | G6: =E6/F6 -> 0.875
B7: Containment strategies based on incident types | E7: 3 | F7: 4 | G7: =E7/F7 -> 0.75
B8: Documented criterias based on incident types to facilitate decision making | E8: 4 | F8: 4 | G8: =E8/F8 -> 1
A9: Evidence gathering and handling Total | E9: =AVERAGE(E10:E11) -> 1 | F9: 4 | G9: =E9/F9 -> 0.25
B10: A detailed log should be kept for all evidence, including the following: Identifying information (e.g., the location, serial number, model number, hostname, media access control (MAC) addresses, and IP addresses of a computer) Name, title, and phone number of each individual who collected or handled the evidence during the investigation Time and date (including time zone) of each occurrence of evidence handling Locations where the evidence was stored. | E10: 1 | F10: 4 | G10: =E10/F10 -> 0.25
B11: Get a snapshot of the system as-is rather than doing so after incident handlers, system administrators, and others have inadvertently altered the state of the machine during the investigation | E11: 1 | F11: 4 | G11: =E11/F11 -> 0.25
A12: Identifying the attacking hosts Total | E12: =AVERAGE(E13:E16) -> 2.5 | F12: 4 | G12: =E12/F12 -> 0.625
B13: Validating if the Attacking Host’s IP Address is spoofed | E13: 2 | F13: 4 | G13: =E13/F13 -> 0.5
B14: Researching the Attacking Host through Search Engines | E14: 3 | F14: 4 | G14: =E14/F14 -> 0.75
B15: Using Incident Databases(Internal and external forums) | E15: 3 | F15: 4 | G15: =E15/F15 -> 0.75
B16: Monitoring Possible Attacker Communication Channels(e.g. IRC) | E16: 2 | F16: 4 | G16: =E16/F16 -> 0.5
A17: Eradication and Reccovery | E17: =AVERAGE(E18:E22) -> 2 | F17: 4 | G17: =E17/F17 -> 0.5
B18: Validating if threat/malware from all the affected hosts in the organization have been eradicated | E18: 3 | F18: 4 | G18: =E18/F18 -> 0.75 | H18: 3.75
B19: Post recovery validations: Normal system functions Remidiate vulnerabilities Patching | E19: 1 | F19: 4 | G19: =E19/F19 -> 0.25 | H19: 1

Sheet 4-POST INCIDENT ACTIVITY (PIA)
A2: 4 - Post Incident Activity (PIA)
A3: Review the following categories in order to assess the cyber security program. L0 (Does Not Exist), L1 (Partial), L2 (Risk Informed), L3 (Repeatable), L4 (Adaptive)
A4: Category | B4: Questionnaire | C4: Client's Summary | D4: Stakeholders Interviewed (Name, Title) | E4: Current Process Score | F4: Target Process Score | G4: % of Current / Target
A5: Post Incident Activity (PIA) Grand Total | E5: =AVERAGE(E6,E9,E14) -> 2.25 | F5: =AVERAGE(F6,F9,F14) -> 4 | G5: =E5/F5 -> 0.5625
A6: Lessons Learned Total | E6: =AVERAGE(E7:E7) -> 2 | F6: =AVERAGE(F7:F7) -> 4 | G6: =E6/F6 -> 0.5
B7: Lessons learned from the incident should be answered and documented as follows: Exactly what happened, and at what times? How well did staff and management perform in dealing with the incident? Were the documented procedures followed? Were they adequate? What information was needed sooner? Were any steps or actions taken that might have inhibited the recovery? What would the staff and management do differently the next time a similar incident occurs? How could information sharing with other organizations have been improved? What corrective actions can prevent similar incidents in the future? What precursors or indicators should be watched for in the future to detect similar incidents? What additional tools or resources are needed to detect, analyze, and mitigate future incidents? | E7: 2 | F7: 4 | G7: =E7/F7 -> 0.5
B8: Follow up report for each incident for future reference | E8: 3 | F8: 4 | G8: =E8/F8 -> 0.75
A9: Using Collected Incident Data Total | E9: =AVERAGE(E10:E13) -> 1.75 | F9: =AVERAGE(F10:F13) -> 4 | G9: =E9/F9 -> 0.4375
B10: Number of Incidents Handled | E10: 3 | F10: 4 | G10: =E10/F10 -> 0.75
B11: Time Per Incident (e.g. FTE, response time) | E11: 1 | F11: 4 | G11: =E11/F11 -> 0.25
B12: Objective Assessment of Each Incident (e.g. impact analysis, trend assessment, efficiency) | E12: 2 | F12: 4 | G12: =E12/F12 -> 0.5
B13: Subjective Assessment of Each Incident(e.g. performance of team, each resource, other teams, customer feedbacks) | E13: 1 | F13: 4 | G13: =E13/F13 -> 0.25
A14: Evidence Retenion Total | E14: =AVERAGE(E15:E18) -> 3 | F14: =AVERAGE(F15:F18) -> 4 | G14: =E14/F14 -> 0.75
B15: Retention policy based on prosecution on attacker | E15: 3 | F15: 4 | G15: =E15/F15 -> 0.75
B16: Retention policy based on organization baseline | E16: 3 | F16: 4 | G16: =E16/F16 -> 0.75

Sheet CSF Core
B1: Source: NIST Cybersecurity Framework Executive Order 13636
A2: Function | B2: Category | C2: Subcategory | D2: Informative References
A3: PREPARATION (PR) | B3: Asset Management (ID.AM): The data, personnel, devices, systems, and facilities that enable the organization to achieve business purposes are identified and managed consistent with their relative importance to business objectives and the organization’s risk strategy. | C3: ID.AM-1: Physical devices and systems within the organization are inventoried | D3: · CCS CSC 1
D4: · COBIT 5 BAI09.01, BAI09.02
D5: · ISA 62443-2-1:2009 4.2.3.4
D6: · ISA 62443-3-3:2013 SR 7.8
D7: · ISO/IEC 27001:2013 A.8.1.1, A.8.1.2
D8: · NIST SP 800-53 Rev. 4 CM-8
C9: ID.AM-2: Software platforms and applications within the organization are inventoried | D9: · CCS CSC 2
D10: · COBIT 5 BAI09.01, BAI09.02, BAI09.05
D11: · ISA 62443-2-1:2009 4.2.3.4
D12: · ISA 62443-3-3:2013 SR 7.8
D13: · ISO/IEC 27001:2013 A.8.1.1, A.8.1.2
D14: · NIST SP 800-53 Rev. 4 CM-8
C15: ID.AM-3: Organizational communication and data flows are mapped | D15: · CCS CSC 1
D16: · COBIT 5 DSS05.02
D17: · ISA 62443-2-1:2009 4.2.3.4
D18: · ISO/IEC 27001:2013 A.13.2.1
D19: · NIST SP 800-53 Rev. 4 AC-4, CA-3, CA-9, PL-8
C20: ID.AM-4: External information systems are catalogued | D20: · COBIT 5 APO02.02
D21: · ISO/IEC 27001:2013 A.11.2.6
D22: · NIST SP 800-53 Rev. 4 AC-20, SA-9
C23: ID.AM-5: Resources (e.g., hardware, devices, data, and software) are prioritized based on their classification, criticality, and business value | D23: · COBIT 5 APO03.03, APO03.04, BAI09.02
D24: · ISA 62443-2-1:2009 4.2.3.6
D25: · ISO/IEC 27001:2013 A.8.2.1
D26: · NIST SP 800-53 Rev. 4 CP-2, RA-2, SA-14
C27: ID.AM-6: Cybersecurity roles and responsibilities for the entire workforce and third-party stakeholders (e.g., suppliers, customers, partners) are established | D27: · COBIT 5 APO01.02, DSS06.03
D28: · ISA 62443-2-1:2009 4.3.2.3.3
D29: · ISO/IEC 27001:2013 A.6.1.1
D30: · NIST SP 800-53 Rev. 4 CP-2, PS-7, PM-11
B31: Business Environment (ID.BE): The organization’s mission, objectives, stakeholders, and activities are understood and prioritized; this information is used to inform cybersecurity roles, responsibilities, and risk management decisions. | C31: ID.BE-1: The organization’s role in the supply chain is identified and communicated | D31: · COBIT 5 APO08.04, APO08.05, APO10.03, APO10.04, APO10.05
D32: · ISO/IEC 27001:2013 A.15.1.3, A.15.2.1, A.15.2.2
D33: · NIST SP 800-53 Rev. 4 CP-2, SA-12
C34: ID.BE-2: The organization’s place in critical infrastructure and its industry sector is identified and communicated | D34: · COBIT 5 APO02.06, APO03.01
D35: · NIST SP 800-53 Rev. 4 PM-8
C36: ID.BE-3: Priorities for organizational mission, objectives, and activities are established and communicated | D36: · COBIT 5 APO02.01, APO02.06, APO03.01
D37: · ISA 62443-2-1:2009 4.2.2.1, 4.2.3.6
D38: · NIST SP 800-53 Rev. 4 PM-11, SA-14
C39: ID.BE-4: Dependencies and critical functions for delivery of critical services are established | D39: · ISO/IEC 27001:2013 A.11.2.2, A.11.2.3, A.12.1.3
D40: · NIST SP 800-53 Rev. 4 CP-8, PE-9, PE-11, PM-8, SA-14
...

Sheet Gaps
B2: Gap Assessment | C2: Gaps Identified
A3: Preparation | B3: Preparing to Handle Incident
B5: Preventing Incidents
A8: Detection and Analysis | B8: Attack Vectors
B10: Signs of an incident
B12: Sources of precursors and indicators
B15: Incident Analysis
B17: Incident documentation
B18: Incident prioritization
B19: Incident Notification
A20: Containment, Eradication and Recovery | B20: Choosing a Containment Strategy
B21: Evidence gathering and handling
B26: Identifying the attacking hosts
B27: Eradication and Recovery
A28: Post Incident Activity | B28: Lessons Learned
B42: Using Collected Incident Data
B43: Evidence Retention

Sheet Recommendations
A2: Cyber Security Recommendations
