Workbook
Name ValidEval: #REF!
Name ValidEval: #REF!
Name ValidEval: #REF!
Name ValidEval: #REF!
Name ValidEval: #REF!
Name ValidEval: #REF!
Name ValidEval: #REF!
Name ValidEval: #REF!
Name ValidEval: #REF!
Name ValidWeights: #REF!
Name ValidWeights: #REF!
Name ValidWeights: #REF!
Name ValidWeights: #REF!
Name ValidWeights: #REF!
Name ValidWeights: #REF!
Name ValidWeights: #REF!
Name ValidWeights: #REF!
Name ValidWeights: #REF!

Sheet Score Card - Cummulative
A2: Cummulative Score
A3: Domain | B3: Sub-Domain | C3: Assessed Score | D3: Peer | E3: Recommended
A4: 1 - Mission and Governance
B5: ='1 - Mission and Governance'!B51 -> 1.1 - Mission | C5: ='1 - Mission and Governance'!C51 -> 0 | D5: ='1 - Mission and Governance'!G51 -> 0 | E5: ='1 - Mission and Governance'!H51 -> 16
B6: ='1 - Mission and Governance'!B52 -> 1.2 - Service Catalogue | C6: ='1 - Mission and Governance'!C52 -> 0 | D6: ='1 - Mission and Governance'!G52 -> 0 | E6: ='1 - Mission and Governance'!H52 -> 32
B7: ='1 - Mission and Governance'!B53 -> 1.3 - Governance | C7: ='1 - Mission and Governance'!C53 -> 0 | D7: ='1 - Mission and Governance'!G53 -> 0 | E7: ='1 - Mission and Governance'!H53 -> 8
B8: ='1 - Mission and Governance'!B54 -> 1.4 - Repeatability | C8: ='1 - Mission and Governance'!C54 -> 0 | D8: ='1 - Mission and Governance'!G54 -> 0 | E8: ='1 - Mission and Governance'!H54 -> 36
A9: 2 - People
B10: ='2 - People'!B95 -> 2.1 - Resourcing | C10: ='2 - People'!C95 -> 0 | D10: ='2 - People'!G95 -> 0 | E10: ='2 - People'!H95 -> 84
B11: ='2 - People'!B96 -> 2.2 - Training | C11: ='2 - People'!C96 -> 0 | D11: ='2 - People'!G96 -> 0 | E11: ='2 - People'!H96 -> 80
B12: ='2 - People'!B97 -> 2.3 - Certifications | C12: ='2 - People'!C97 -> 0 | D12: ='2 - People'!G97 -> 0 | E12: ='2 - People'!H97 -> 36
B13: ='2 - People'!B98 -> 2.4 - Relevant Experience | C13: ='2 - People'!C98 -> 0 | D13: ='2 - People'!G98 -> 0 | E13: ='2 - People'!H98 -> 32
B14: ='2 - People'!B99 -> 2.5 - Skills Assessment | C14: ='2 - People'!C99 -> 0 | D14: ='2 - People'!G99 -> 0 | E14: ='2 - People'!H99 -> 24
B15: ='2 - People'!B100 -> 2.6 - Career Path | C15: ='2 - People'!C100 -> 0 | D15: ='2 - People'!G100 -> 0 | E15: ='2 - People'!H100 -> 20
B16: ='2 - People'!B101 -> 2.7 - Leadership | C16: ='2 - People'!C101 -> 0 | D16: ='2 - People'!G101 -> 0 | E16: ='2 - People'!H101 -> 48
A17: 3 - Process
B18: ='3 - Process'!B177 -> 3.1 - SOC Threat Management | C18: ='3 - Process'!C177 -> 0 | D18: ='3 - Process'!G167 -> 0 | E18: ='3 - Process'!H167 -> 172
B19: ='3 - Process'!B178 -> 3.2 - SOC Analytical Process | C19: ='3 - Process'!C178 -> 0 | D19: ='3 - Process'!G168 -> 0 | E19: ='3 - Process'!H168 -> 91
B20: ='3 - Process'!B179 -> 3.3 - SOC Engineering Processes | C20: ='3 - Process'!C179 -> 0 | D20: ='3 - Process'!G169 -> 0 | E20: ='3 - Process'!H169 -> 48
B21: ='3 - Process'!B180 -> 3.4 - SOC Operations and Continuity | C21: ='3 - Process'!C180 -> 0 | D21: ='3 - Process'!G170 -> 0 | E21: ='3 - Process'!H170 -> 160
B22: ='3 - Process'!B181 -> 3.5 - SOC Incident Coordination | C22: ='3 - Process'!C181 -> 0 | D22: ='3 - Process'!G171 -> 0 | E22: ='3 - Process'!H171 -> 32
B23: ='3 - Process'!B182 -> 3.6 - SOC Portfolio Management | C23: ='3 - Process'!C182 -> 0 | D23: ='3 - Process'!G172 -> 0 | E23: ='3 - Process'!H172 -> 104
A24: 4 - Technology
B25: ='4 - Technology Functional'!B196 -> 4.1 - Security Information and Event Management | C25: ='4 - Technology Functional'!C196 -> 0 | D25: ='4 - Technology Functional'!D196 -> 0 | E25: ='4 - Technology Functional'!E196 -> 76
B26: ='4 - Technology Functional'!B197 -> 4.2 - Intelligence Correlation | C26: ='4 - Technology Functional'!C197 -> 0 | D26: ='4 - Technology Functional'!D197 -> 0 | E26: ='4 - Technology Functional'!E197 -> 36
B27: ='4 - Technology Functional'!B198 -> 4.3 - Architecture | C27: ='4 - Technology Functional'!C198 -> 0 | D27: ='4 - Technology Functional'!D198 -> 0 | E27: ='4 - Technology Functional'!E198 -> 88
B28: ='4 - Technology Functional'!B199 -> 4.4 - Correlation | C28: ='4 - Technology Functional'!C199 -> 0 | D28: ='4 - Technology Functional'!D199 -> 0 | E28: ='4 - Technology Functional'!E199 -> 152
B29: ='4 - Technology Functional'!B200 -> 4.5 - Reporting | C29: ='4 - Technology Functional'!C200 -> 0 | D29: ='4 - Technology Functional'!D200 -> 0 | E29: ='4 - Technology Functional'!E200 -> 120
B30: ='4 - Technology Functional'!B201 -> 4.6 - SOC Engineering | C30: ='4 - Technology Functional'!C201 -> 0 | D30: ='4 - Technology Functional'!D201 -> 0 | E30: ='4 - Technology Functional'!E201 -> 192
B31: ='4 - Technology Functional'!B202 -> 4.7 - SOC Information Lifecycle Management | C31: ='4 - Technology Functional'!C202 -> 0 | D31: ='4 - Technology Functional'!D202 -> 0 | E31: ='4 - Technology Functional'!E202 -> 24
A32: 5 - Coverage
B33: ='5 - Coverage'!B135 -> 5.1 - Infrastructure Event Coverage | C33: ='5 - Coverage'!C135 -> 0 | D33: ='5 - Coverage'!D135 -> 0 | E33: ='5 - Coverage'!E135 -> 36
B34: ='5 - Coverage'!B136 -> 5.2 - Security Devices Coverage | C34: ='5 - Coverage'!C136 -> 0 | D34: ='5 - Coverage'!D136 -> 0 | E34: ='5 - Coverage'!E136 -> 64
B35: ='5 - Coverage'!B137 -> 5.3 - Advanced Threat Coverage | C35: ='5 - Coverage'!C137 -> 0 | D35: ='5 - Coverage'!D137 -> 0 | E35: ='5 - Coverage'!E137 -> 32
B36: ='5 - Coverage'!B138 -> 5.4 - Network Device Coverage | C36: ='5 - Coverage'!C138 -> 0 | D36: ='5 - Coverage'!D138 -> 0 | E36: ='5 - Coverage'!E138 -> 52
B37: ='5 - Coverage'!B139 -> 5.5 - Application Coverage | C37: ='5 - Coverage'!C139 -> 0 | D37: ='5 - Coverage'!D139 -> 0 | E37: ='5 - Coverage'!E139 -> 16
B38: ='5 - Coverage'!B140 -> 5.6 - Use Case Enablers | C38: ='5 - Coverage'!C140 -> 0 | D38: ='5 - Coverage'!D140 -> 0 | E38: ='5 - Coverage'!E140 -> 152
B39: ='5 - Coverage'!B141 -> 5.7 - Reports | C39: ='5 - Coverage'!C141 -> 0 | D39: ='5 - Coverage'!D141 -> 0 | E39: ='5 - Coverage'!E141 -> 120

Sheet Score Card - Percentage
A2: Score Percentage
A3: Domain | B3: Sub-Domain | C3: Assessed Score | D3: Peer | E3: Recommended
A4: 1 - Mission and Governance
B5: ='1 - Mission and Governance'!B51 -> 1.1 - Mission | C5: 0.12 | D5: ='1 - Mission and Governance'!G60 -> 0 | E5: ='1 - Mission and Governance'!H60 -> 0.8
B6: ='1 - Mission and Governance'!B52 -> 1.2 - Service Catalogue | C6: 0.02 | D6: ='1 - Mission and Governance'!G61 -> 0 | E6: ='1 - Mission and Governance'!H61 -> 0.8
B7: ='1 - Mission and Governance'!B53 -> 1.3 - Governance | C7: 0.13 | D7: ='1 - Mission and Governance'!G62 -> 0 | E7: ='1 - Mission and Governance'!H62 -> 0.8
B8: ='1 - Mission and Governance'!B54 -> 1.4 - Repeatability | C8: 0.9 | D8: ='1 - Mission and Governance'!G63 -> 0 | E8: ='1 - Mission and Governance'!H63 -> 0.8
A9: 2 - People
B10: ='2 - People'!B95 -> 2.1 - Resourcing | C10: ='2 - People'!C106 -> 0 | D10: ='2 - People'!G106 -> 0 | E10: ='2 - People'!H106 -> 0.8
B11: ='2 - People'!B96 -> 2.2 - Training | C11: ='2 - People'!C107 -> 0 | D11: ='2 - People'!G107 -> 0 | E11: ='2 - People'!H107 -> 0.8
B12: ='2 - People'!B97 -> 2.3 - Certifications | C12: ='2 - People'!C108 -> 0 | D12: ='2 - People'!G108 -> 0 | E12: ='2 - People'!H108 -> 0.8
B13: ='2 - People'!B98 -> 2.4 - Relevant Experience | C13: ='2 - People'!C109 -> 0 | D13: ='2 - People'!G109 -> 0 | E13: ='2 - People'!H109 -> 0.8
B14: ='2 - People'!B99 -> 2.5 - Skills Assessment | C14: ='2 - People'!C110 -> 0 | D14: ='2 - People'!G110 -> 0 | E14: ='2 - People'!H110 -> 0.8
B15: ='2 - People'!B100 -> 2.6 - Career Path | C15: ='2 - People'!C111 -> 0 | D15: ='2 - People'!G111 -> 0 | E15: ='2 - People'!H111 -> 0.8
B16: ='2 - People'!B101 -> 2.7 - Leadership | C16: ='2 - People'!C112 -> 0 | D16: ='2 - People'!G112 -> 0 | E16: ='2 - People'!H112 -> 0.8
A17: 3 - Process
B18: ='3 - Process'!B177 -> 3.1 - SOC Threat Management | C18: ='3 - Process'!C187 -> 0 | D18: ='3 - Process'!G177 -> 0 | E18: ='3 - Process'!H177 -> 0.8
B19: ='3 - Process'!B178 -> 3.2 - SOC Analytical Process | C19: ='3 - Process'!C188 -> 0 | D19: ='3 - Process'!G178 -> 0 | E19: ='3 - Process'!H178 -> 0.79130435
B20: ='3 - Process'!B179 -> 3.3 - SOC Engineering Processes | C20: ='3 - Process'!C189 -> 0 | D20: ='3 - Process'!G179 -> 0 | E20: ='3 - Process'!H179 -> 0.8
B21: ='3 - Process'!B180 -> 3.4 - SOC Operations and Continuity | C21: ='3 - Process'!C190 -> 0 | D21: ='3 - Process'!G180 -> 0 | E21: ='3 - Process'!H180 -> 0.8
B22: ='3 - Process'!B181 -> 3.5 - SOC Incident Coordination | C22: ='3 - Process'!C191 -> 0 | D22: ='3 - Process'!G181 -> 0 | E22: ='3 - Process'!H181 -> 0.8
B23: ='3 - Process'!B182 -> 3.6 - SOC Portfolio Management | C23: ='3 - Process'!C192 -> 0 | D23: ='3 - Process'!G182 -> 0 | E23: ='3 - Process'!H182 -> 0.8
A24: 4 - Technology
B25: ='4 - Technology Functional'!B196 -> 4.1 - Security Information and Event Management | C25: ='4 - Technology Functional'!C207 -> 0 | D25: ='4 - Technology Functional'!D207 -> 0 | E25: ='4 - Technology Functional'!E207 -> 0.8
B26: ='4 - Technology Functional'!B197 -> 4.2 - Intelligence Correlation | C26: ='4 - Technology Functional'!C208 -> 0 | D26: ='4 - Technology Functional'!D208 -> 0 | E26: ='4 - Technology Functional'!E208 -> 0.8
B27: ='4 - Technology Functional'!B198 -> 4.3 - Architecture | C27: ='4 - Technology Functional'!C209 -> 0 | D27: ='4 - Technology Functional'!D209 -> 0 | E27: ='4 - Technology Functional'!E209 -> 0.8
B28: ='4 - Technology Functional'!B199 -> 4.4 - Correlation | C28: ='4 - Technology Functional'!C210 -> 0 | D28: ='4 - Technology Functional'!D210 -> 0 | E28: ='4 - Technology Functional'!E210 -> 0.8
B29: ='4 - Technology Functional'!B200 -> 4.5 - Reporting | C29: ='4 - Technology Functional'!C211 -> 0 | D29: ='4 - Technology Functional'!D211 -> 0 | E29: ='4 - Technology Functional'!E211 -> 0.8
B30: ='4 - Technology Functional'!B201 -> 4.6 - SOC Engineering | C30: ='4 - Technology Functional'!C212 -> 0 | D30: ='4 - Technology Functional'!D212 -> 0 | E30: ='4 - Technology Functional'!E212 -> 0.8
B31: ='4 - Technology Functional'!B202 -> 4.7 - SOC Information Lifecycle Management | C31: ='4 - Technology Functional'!C213 -> 0 | D31: ='4 - Technology Functional'!D213 -> 0 | E31: ='4 - Technology Functional'!E213 -> 0.8
A32: 5 - Coverage
B33: ='5 - Coverage'!B135 -> 5.1 - Infrastructure Event Coverage | C33: ='5 - Coverage'!C146 -> 0 | D33: ='5 - Coverage'!D146 -> 0 | E33: ='5 - Coverage'!E146 -> 0.8
B34: ='5 - Coverage'!B136 -> 5.2 - Security Devices Coverage | C34: ='5 - Coverage'!C147 -> 0 | D34: ='5 - Coverage'!D147 -> 0 | E34: ='5 - Coverage'!E147 -> 0.8
B35: ='5 - Coverage'!B137 -> 5.3 - Advanced Threat Coverage | C35: ='5 - Coverage'!C148 -> 0 | D35: ='5 - Coverage'!D148 -> 0 | E35: ='5 - Coverage'!E148 -> 0.8
B36: ='5 - Coverage'!B138 -> 5.4 - Network Device Coverage | C36: ='5 - Coverage'!C149 -> 0 | D36: ='5 - Coverage'!D149 -> 0 | E36: ='5 - Coverage'!E149 -> 0.8
B37: ='5 - Coverage'!B139 -> 5.5 - Application Coverage | C37: ='5 - Coverage'!C150 -> 0 | D37: ='5 - Coverage'!D150 -> 0 | E37: ='5 - Coverage'!E150 -> 0.8
B38: ='5 - Coverage'!B140 -> 5.6 - Use Case Enablers | C38: ='5 - Coverage'!C151 -> 0 | D38: ='5 - Coverage'!D151 -> 0 | E38: ='5 - Coverage'!E151 -> 0.8
B39: ='5 - Coverage'!B141 -> 5.7 - Reports | C39: ='5 - Coverage'!C152 -> 0 | D39: ='5 - Coverage'!D152 -> 0 | E39: ='5 - Coverage'!E152 -> 0.8

Sheet Score Card - Graphs
A2: Score Percentage
A3: Domain | B3: Sub-Domain | C3: Assessed Score | D3: Peer | E3: Recommended
A4: 1 - Mission and Governance
A19: 2 - People
A36: 3 - Process
A56: 4 - Technology
A75: 5 - Coverage

Sheet CoBIT maturity key
A2: CoBIT Metric/Maturity Model
A3: Metric | C3: Activity | D3: Assigned Responsibilities | E3: Documents in place | F3: KPI/KGI
A4: Level 0 - Does not exist | B4: 0 | C4: No awareness of the importance of issues related to the activity. No monitoring is performed. No documentation exists. No activity improvement actions take place. | D4: No RACI relationship assigned | E4: 0 | F4: 0
A5: Level 1 - Initial | B5: 1 | C5: Some awareness of the importance of issues related to the activity. No monitoring is performed. No documentation exists. No activity improvement actions take place. | D5: 25 % of RACI-relationships assigned. | E5: 0.2 | F5: 0.2
A6: Level 2 - Repeatable | B6: 2 | C6: Individuals have knowledge about issues related to the activity and take actions accordingly. No monitoring is performed. No documentation exists. No activity improvement actions take place. | D6: More than 26 % of RACI relationships assigned. 25 % or less of the identified relationships are in line with COBIT. | E6: 0.4 | F6: 0.4
A7: Level 3 - Defined | B7: 3 | C7: Affected personnel are trained in the means and goals of the activity. No monitoring is performed. Documentation is present. No activity improvement actions take place. | D7: More than 26 % of RACIrelationships assigned. 26- 74 % of the identified relationships are in line with COBIT. | E7: 0.6 | F7: 0.6
A8: Level 4 - Managed | B8: 4 | C8: Affected personnel are trained in the means and goals of the activity. Monitoring is performed. Documentation is present. The activity is under constant improvement. Automated tools are employed in a limited and fragmented way | D8: re than 51 % of RACI relationships assigned. 51- 99 % of the identified relationships are in line with COBIT. | E8: 0.8 | F8: 0.8
A9: Level 5 - Optimized | B9: 5 | C9: Affected personnel are trained in the means and goals of the activity. Monitoring is performed. Documentation is present. Automated tools are employed in an integrated way, to improve quality and effectiveness of the activity. | D9: 100 % of RACI-relationships assigned. 100 % of the identified relationships are in line with COBIT. | E9: 1 | F9: 1

Sheet 0 - General Questions
A2: 0 - Roadmap Questionairre
A3: Please enter a response for each question | B3: Response
A4: Business Profile
A5: Client Name | B5: InterGlobe Aviation Pvt. Ltd.
A6: Number of Employees | B6: 26000
A7: Number of Customer (preferrably by region) | B7: 1
A8: Number of Offices | B8: Multiple
A9: Countries of Operations (please specify countries and if possible the approx number of customers by region) | B9: 33
A10: Compliance Drivers
A11: What compliance frameworks are pertitent to the organization? | B11: ISO 27001
A12: What industry standards would the organization wish to consider for the assessment? | B12: ISO 27001
A13: Has internal (or external) audit rendered any audit points on Logging, Monitoring or Reporting? If so, if you can please provide the findings. | B13: Check
A14: Information Security Policy
A15: Please provide any corporate information security policy. | B15: Yes
A16: Is there a policy on data classification? | B16: Check
A17: Is there assets that have been classified as business critical within the governance of this document? If so, where are they located? | B17: Yes, the critical applications are hsoted in the Data Center/ Azure Cloud
A18: Is there a formalized methodology for threat modeling and use case development? | B18: Yes
A19: High level Service Level Objectives
A20: Is there a document that defines the SLO for responding to high severity alarm conditions that may be generated by the future SOC? For example, if an organization is affected by a business critical threat, would the response expectation be 15, 30 minutes, two (2) hours etc.? | B20: Yes, SLAs are defined in the IR plan
A21: Financial model
A22: For the financial model, should Deloitte consider a three, five or other year model? | B22: 3 year multiyear engagement
A23: Should Deloitte use a NPV of 5% for the cost forecast?
A24: Is there a primary IT investment focus (strategic, information, transactional, infrastructure)?
A25: Is there a defined Business Risk Measurement Model?
A26: Has the company allocated Business Risk Financing?
A27: Service Catalogue
A28: Please enter the current service catalogue for the SOC. For example, what functions are being covered by the current SOC (e.g. monitoring, cyber threat intelligence, malware reconstruction etc)?
A29: Is there an enterprise strategy on vulnerability monitoring tracking? | B29: Yes, Tenable VMS in place and all the vulnerabilities are tracked in SNOW
A30: If so, would an organization like Deloitte to include this in the Services Catalogue. | B30: Already included
A31: Typically this is not considered a core SOC service and can result in expanded scope, but some clients have asked that this be included in the extended SOC’s domicile of coverage. | B31: Not included in core SOC services for IndiGo
A32: Is there an enterprise strategy on Cyber Threat Intelligence? If so, are there resources currently allocated to this function? | B32: Yes, basic CTI services are provided by Deloitte
A33: Is there an enterprise strategy on Role and Group Certification? If so, are there resources currently allocated to this function? | B33: Yes, preperation for ISO 27001 certification is in progress
A34: If not, would an organization like Deloitte to include this in the Services Catalogue. | B34: Already included
A35: Typically this is not considered a core SOC service and can result in expanded scope, but some clients have asked that this be included in the extended SOC’s domicile of coverage. | B35: Not included in core SOC services for IndiGo
A36: Is there an enterprise strategy on Malware Analysis? If so, are there resources currently allocated to this function?
A37: If not, would an organization like Deloitte to include this in the Services Catalogue.
A38: Is there an enterprise strategy on Compliance Reporting, Monitoring and Tracking? If so, are there resources currently allocated to this function?
A39: Would an organization like Deloitte to include this in the Services Catalogue?
A40: Would an organization like Deloitte to include Security Advisory Services as part of the SOC’s Services Catalogue? Security Advisory services include monitoring security threat advisories and disseminating it to the applicable teams.
A41: Typically this is not considered a core SOC service and can result in expanded scope, but some clients have asked that this be included in the extended SOC’s domicile of coverage.
...

Sheet Sheet1

Sheet 1 - Mission and Governance
A2: 1 - Mission and Governance
A3: Index | B3: Control Objective | C3: Current | D3: Peer | E3: Recommended | F3: Maximum | G3: Peer | H3: Recommended | I3: Maximum | R3: Comments
A4: 1.1 - Mission
A5: 1.1.1 | B5: Does the SOC have an established Mission? | C5: Level 5 - Optimized | H5: 4 | I5: 5 | J5: Sample Company specific only, with group charter.
A6: 1.1.2 | B6: Is the Mission aligned with the corporate Vision? | C6: Level 5 - Optimized | H6: 4 | I6: 5
A7: 1.1.3 | B7: Is the SOC stakeholder group clearly documented? | C7: Level 5 - Optimized | H7: 4 | I7: 5 | J7: Operation mgmt. IT Security Advisory Board. Moving into ITIL framework.
A8: 1.1.4 | B8: Are staff trained on the Mission and how it needs to aligns with operating procedures? | C8: Level 3 - Defined | H8: 4 | I8: 5 | J8: Operational manual.
A9: 1.1.5 | B9: Does the SOC's metric program evaluate against the Mission? | C9: Level 3 - Defined | H9: 4
A10: 1.1.6 | B10: The SOC has an risk management plan that considers the Governance model?
A11: 1.1.7 | B11: Governance is reviewed on an annual basis to ensure adherence to Mission and Vision? | C11: Level 4 - Managed
A12: 1.2 - Service Catalogue
A13: 1.2.1 | B13: Does the SOC have a documented service catalogue? | C13: Level 5 - Optimized | H13: 4 | I13: 5 | J13: IPS coverage is only very limited to certains clients at the moment.
A14: 1.2.2 | B14: Does the SOC communicate the service catalogue to the lines of business? | C14: Level 5 - Optimized | H14: 4 | I14: 5 | K14: Vulnerability and Threat Management Report (Aaron Morrison). Target state micro/macro designs. Part of the Threat and Vulnerability Pillar
A15: 1.2.3 | B15: Does the SOC provide Service Level Objectives against the service catalogue? | C15: Level 5 - Optimized | H15: 4 | I15: 5
A16: 1.2.4 | B16: Does the SOC evaluate performance and report on metrics against the service catalogue? | C16: Level 5 - Optimized | H16: 4 | I16: 5
A17: 1.2.5 | B17: Does the SOC assess resource loading based on the service catalogue? | H17: 4 | I17: 5
A18: 1.2.6 | B18: Does the SOC evaluate resource utilization by service catalogue on a quarterly basis? | H18: 4 | I18: 5
A19: 1.2.7 | B19: Is the SOC service catalogue evaluated with the business stakeholder on an annual basis? | C19: Level 5 - Optimized | H19: 4 | I19: 5
A20: 1.2.8 | B20: Does the SOC ensure appropriate skills maintenance based on the service catalogue? | C20: Level 5 - Optimized | H20: 4 | I20: 5
A21: 1.3 - Governance
A22: 1.3.1 | B22: Does the SOC have a documented governance model? | C22: Level 3 - Defined | H22: 4 | I22: 5
A23: 1.3.2 | B23: Does the SOC maintain list of policies and due care standards that are unique to SOC operations (and not part of the organization's standard policy documentation)? | C23: Level 3 - Defined | H23: 4 | I23: 5
A24: 1.3.3 | B24: Does the SOC maintain and evaluate a repository of unified control objectives? | C24: Level 2 - Repeatable
A25: 1.3.4 | B25: Are the unified control objectives mapped to the organization's regulatory, compliance and industry standards? | C25: Level 2 - Repeatable
A26: 1.3.5 | B26: Does the reporting structure align with the unified control objectives. | C26: Level 2 - Repeatable
A27: 1.3.6 | B27: The SOC has automated synchronization of compliance meta-data between SIEM and eGRC. | C27: Level 0 - Does not exist
A28: 1.4 - Repeatability
A29: 1.4.1 | B29: Does the SOC have an established performance management program? | C29: Level 5 - Optimized | H29: 4 | I29: 5
A30: 1.4.2 | B30: Has the metrics program been aligned with the overall SOC Mission? | C30: Level 5 - Optimized | H30: 4 | I30: 5
A31: 1.4.3 | B31: Are performance metrics reported to business stakeholder on an annual basis? | C31: Level 5 - Optimized | H31: 4 | I31: 5
A32: 1.4.4 | B32: Are performance metrics communicated to all levels of the SOC? | C32: Level 5 - Optimized | H32: 4 | I32: 5
A33: 1.4.5 | B33: Are the performance metrics aligned with compliance goals? | C33: Level 4 - Managed | H33: 4 | I33: 5
A34: 1.4.6 | B34: Are case management timer metrics retained and reported on? | C34: Level 5 - Optimized | H34: 4 | I34: 5
A35: 1.4.7 | B35: Does the SOC use metrics/performance measures as an input into decision making processes and prioritization of activities, resources and funding? | H35: 4 | I35: 5
A36: 1.4.8 | B36: Are SOC metrics reviewed by independent parties on an annual basis, at a minimum? | H36: 4 | I36: 5
A37: 1.4.9 | B37: Are independent reviews performed of SOC logs/alarms for completeness and consistency with reported performance? | H37: 4 | I37: 5
A38: 1.5 - Intra-organization interfaces
B39: Does the SOC have formalized RACI between dependent organizational functions?
A40: 1.5.1 | B40: Does the SOC have formalized engagement processes and standards to interact with HR, about employee investigations? | C40: Level 3 - Defined | H40: 4 | I40: 5
A41: 1.5.2 | B41: Does the SOC have formalized engagement processes and standards to interact with Operations? | C41: Level 4 - Managed | H41: 4 | I41: 5
...

Sheet 2.2 - People Matrix
A2: 2.1 - People Loading Matrix
A3: Please enter the number of resources, role etc., for the current SOC
A4: Role | B4: Function | C4: Number of resources | D4: Peer | E4: Recommended | F4: Maximum
B94: SUMMARY Score | C94: =#REF! -> #REF! | D94: =#REF! -> #REF! | E94: =#REF! -> #REF! | F94: =#REF! -> #REF!
B95: =A5 -> 0 | C95: =SUM(C6:C26) -> 0 | D95: =SUM(D6:D26) -> 0 | E95: =SUM(E6:E26) -> 0 | F95: =SUM(F6:F26) -> 0
B96: =A27 -> 0 | C96: =SUM(C28:C47) -> 0 | D96: =SUM(D28:D47) -> 0 | E96: =SUM(E28:E47) -> 0 | F96: =SUM(F28:F47) -> 0
B97: =A48 -> 0 | C97: =SUM(C49:C57) -> 0 | D97: =SUM(D49:D57) -> 0 | E97: =SUM(E49:E57) -> 0 | F97: =SUM(F49:F57) -> 0
B98: =A58 -> 0 | C98: =SUM(C59:C66) -> 0 | D98: =SUM(D59:D66) -> 0 | E98: =SUM(E59:E66) -> 0 | F98: =SUM(F59:F66) -> 0
B99: =A67 -> 0 | C99: =SUM(C68:C73) -> 0 | D99: =SUM(D68:D73) -> 0 | E99: =SUM(E68:E73) -> 0 | F99: =SUM(F68:F73) -> 0
B100: =A74 -> 0 | C100: =SUM(C75:C79) -> 0 | D100: =SUM(D75:D79) -> 0 | E100: =SUM(E75:E79) -> 0 | F100: =SUM(F75:F79) -> 0
B101: =A80 -> 0 | C101: =SUM(C81:C92) -> 0 | D101: =SUM(D81:D92) -> 0 | E101: =SUM(E81:E92) -> 0 | F101: =SUM(F81:F92) -> 0
B102: TOTAL | C102: =SUM(C95:C99) -> 0 | D102: =SUM(D95:D99) -> 0 | E102: =SUM(E95:E99) -> 0 | F102: =SUM(F95:F99) -> 0
B105: Summary Percentage | C105: =C94 -> #REF! | D105: =D94 -> #REF! | E105: =E94 -> #REF! | F105: =F94 -> #REF!
B106: =B95 -> 0 | C106: =C95/#REF! -> #REF! | D106: =D95/#REF! -> #REF! | E106: =E95/#REF! -> #REF! | F106: =F95/#REF! -> #REF!
B107: =B96 -> 0 | C107: =C96/#REF! -> #REF! | D107: =D96/#REF! -> #REF! | E107: =E96/#REF! -> #REF! | F107: =F96/#REF! -> #REF!
B108: =B97 -> 0 | C108: =C97/#REF! -> #REF! | D108: =D97/#REF! -> #REF! | E108: =E97/#REF! -> #REF! | F108: =F97/#REF! -> #REF!
B109: =B98 -> 0 | C109: =C98/#REF! -> #REF! | D109: =D98/#REF! -> #REF! | E109: =E98/#REF! -> #REF! | F109: =F98/#REF! -> #REF!
B110: =B99 -> 0 | C110: =C99/#REF! -> #REF! | D110: =D99/#REF! -> #REF! | E110: =E99/#REF! -> #REF! | F110: =F99/#REF! -> #REF!
B111: =B100 -> 0 | C111: =C100/#REF! -> #REF! | D111: =D100/#REF! -> #REF! | E111: =E100/#REF! -> #REF! | F111: =F100/#REF! -> #REF!
B112: =B101 -> 0 | C112: =C101/#REF! -> #REF! | D112: =D101/#REF! -> #REF! | E112: =E101/#REF! -> #REF! | F112: =F101/#REF! -> #REF!
B113: TOTAL | C113: =C102/#REF! -> #REF! | D113: =D102/#REF! -> #REF! | E113: =E102/#REF! -> #REF! | F113: =F102/#REF! -> #REF!

Sheet 2.3 - Resource Costing Model
A2: 2.3 - Resource Costing Model
A3: Please enter the fully loaded FTE costing for the existing SOC
A4: Role | B4: Function | C4: Fully loaded cost per resource | D4: Peer | E4: Recommended | F4: Maximum
B94: SUMMARY Score | C94: =#REF! -> #REF! | D94: =#REF! -> #REF! | E94: =#REF! -> #REF! | F94: =#REF! -> #REF!
B95: =A5 -> 0 | C95: =SUM(C6:C26) -> 0 | D95: =SUM(D6:D26) -> 0 | E95: =SUM(E6:E26) -> 0 | F95: =SUM(F6:F26) -> 0
B96: =A27 -> 0 | C96: =SUM(C28:C47) -> 0 | D96: =SUM(D28:D47) -> 0 | E96: =SUM(E28:E47) -> 0 | F96: =SUM(F28:F47) -> 0
B97: =A48 -> 0 | C97: =SUM(C49:C57) -> 0 | D97: =SUM(D49:D57) -> 0 | E97: =SUM(E49:E57) -> 0 | F97: =SUM(F49:F57) -> 0
B98: =A58 -> 0 | C98: =SUM(C59:C66) -> 0 | D98: =SUM(D59:D66) -> 0 | E98: =SUM(E59:E66) -> 0 | F98: =SUM(F59:F66) -> 0
B99: =A67 -> 0 | C99: =SUM(C68:C73) -> 0 | D99: =SUM(D68:D73) -> 0 | E99: =SUM(E68:E73) -> 0 | F99: =SUM(F68:F73) -> 0
B100: =A74 -> 0 | C100: =SUM(C75:C79) -> 0 | D100: =SUM(D75:D79) -> 0 | E100: =SUM(E75:E79) -> 0 | F100: =SUM(F75:F79) -> 0
B101: =A80 -> 0 | C101: =SUM(C81:C92) -> 0 | D101: =SUM(D81:D92) -> 0 | E101: =SUM(E81:E92) -> 0 | F101: =SUM(F81:F92) -> 0
B102: TOTAL | C102: =SUM(C95:C99) -> 0 | D102: =SUM(D95:D99) -> 0 | E102: =SUM(E95:E99) -> 0 | F102: =SUM(F95:F99) -> 0
B105: Summary Percentage | C105: =C94 -> #REF! | D105: =D94 -> #REF! | E105: =E94 -> #REF! | F105: =F94 -> #REF!
B106: =B95 -> 0 | C106: =C95/#REF! -> #REF! | D106: =D95/#REF! -> #REF! | E106: =E95/#REF! -> #REF! | F106: =F95/#REF! -> #REF!
B107: =B96 -> 0 | C107: =C96/#REF! -> #REF! | D107: =D96/#REF! -> #REF! | E107: =E96/#REF! -> #REF! | F107: =F96/#REF! -> #REF!
B108: =B97 -> 0 | C108: =C97/#REF! -> #REF! | D108: =D97/#REF! -> #REF! | E108: =E97/#REF! -> #REF! | F108: =F97/#REF! -> #REF!
B109: =B98 -> 0 | C109: =C98/#REF! -> #REF! | D109: =D98/#REF! -> #REF! | E109: =E98/#REF! -> #REF! | F109: =F98/#REF! -> #REF!
B110: =B99 -> 0 | C110: =C99/#REF! -> #REF! | D110: =D99/#REF! -> #REF! | E110: =E99/#REF! -> #REF! | F110: =F99/#REF! -> #REF!
B111: =B100 -> 0 | C111: =C100/#REF! -> #REF! | D111: =D100/#REF! -> #REF! | E111: =E100/#REF! -> #REF! | F111: =F100/#REF! -> #REF!
B112: =B101 -> 0 | C112: =C101/#REF! -> #REF! | D112: =D101/#REF! -> #REF! | E112: =E101/#REF! -> #REF! | F112: =F101/#REF! -> #REF!
B113: TOTAL | C113: =C102/#REF! -> #REF! | D113: =D102/#REF! -> #REF! | E113: =E102/#REF! -> #REF! | F113: =F102/#REF! -> #REF!

Sheet 4.1 - SIEM
A2: 4 - ArcSight Specific Questions
A3: Index | B3: Control Objective | C3: Response
A4: Architecture
B5: How many SmartConnectors exist?
B6: How many Connector Appliances or SmartConnector servers?
B7: How many Loggers does the organization have and which model?
B8: How many ESM managers does the organization have?
B9: How many ESM databases does the organization have?
A10: Rates
B11: Please document the SmartConnector insertion rate for the Connectors?
B12: Please document the Logger input (receiver) eps per Logger
B13: Please document the ESM input eps?
A14: Version
B15: What are the Connector versions?
B16: What are the Logger version (if separate)?
B17: What is the ESM version?
B18: What is the Oracle DB version?

Sheet 2 - People
A2: 2 - People Control Objectives
A3: Index | B3: Control Objective | C3: Current | D3: Peer | E3: Recommended | F3: Maximum | G3: Peer | H3: Recommended | I3: Maximum | J3: Comments
A4: 2.1 - Resourcing
A5: 2.1.1 | B5: Does the organization have analyst coverage for 24x7x365? | C5: Level 5 - Optimized | H5: 4 | I5: 5 | J5: Yes, 24x7x365 Opertions
A6: 2.1.2 | B6: Does the organization have a minimum of two Level 1 analysts for business hours shifts? | C6: Level 5 - Optimized | H6: 4 | I6: 5
A7: 2.1.3 | B7: Does the organization have a minimum of two resources (L1 - L2 mix) for graveyard shifts? | C7: Level 5 - Optimized | H7: 4 | I7: 5
A8: 2.1.4 | B8: Does the organization have a minimum of 1:4 leverage for L1 versus L2? | C8: Level 5 - Optimized | H8: 4 | I8: 5
A9: 2.1.5 | B9: Does the organization have resources that provide overlap between shifts? | C9: Level 5 - Optimized | H9: 4 | I9: 5
A10: 2.1.6 | B10: Does the organization have contingency resources for shifts? | C10: Level 3 - Defined | H10: 4 | I10: 5
A11: 2.1.7 | B11: Does the organization have defined roles and responsibilies? | C11: Level 1 - Initial | H11: 4 | I11: 5
A12: 2.1.8 | B12: Does the SOC have a minimum of four shifts per week | C12: Level 5 - Optimized | H12: 4 | I12: 5
A13: 2.1.9 | B13: Do you evaluate analysts against those defined R&R? | H13: 4 | I13: 5
A14: 2.1.10 | B14: Does the organization have documented R&R for teams you interact with? | H14: 4 | I14: 5
A15: 2.1.11 | B15: Does the organization have a dedicated SOC engineer? | C15: Level 5 - Optimized | H15: 4 | I15: 5
A16: 2.1.12 | B16: Does the SOC engineer have an assigned backup? | C16: Level 5 - Optimized | H16: 4 | I16: 5
A17: 2.1.13 | B17: Does the organization have a management issue escalation process? | C17: Level 5 - Optimized | H17: 4 | I17: 5
A18: 2.1.14 | B18: Do all key positions have designated backups? | C18: Level 5 - Optimized | H18: 4 | I18: 5
A19: 2.1.15 | B19: Does the organization have a contact list and procedure for engaging other areas? | C19: Level 5 - Optimized | H19: 4 | I19: 5
A20: 2.1.16 | B20: Is there a defined audience and method for all SOC reports? | C20: Level 5 - Optimized | H20: 4 | I20: 5
A21: 2.1.17 | B21: Is there a dedicated SOC manager? | C21: Level 5 - Optimized | H21: 4 | I21: 5
A22: 2.1.18 | B22: Where in the Security Org, does the SOC manager report? | C22: Level 5 - Optimized | H22: 4 | I22: 5
A23: 2.1.19 | B23: Is there a defined organizational stucture for the SOC? | C23: Level 4 - Managed | H23: 4 | I23: 5
A24: 2.1.20 | B24: Is there a defined organizational structure for teams interfacing with the SOC on a regular basis? | C24: Level 4 - Managed | H24: 4 | I24: 5
A25: 2.1.21 | B25: Is there a defined escalation path for SOC incidents? | C25: Level 4 - Managed | H25: 4 | I25: 5
A26: 2.1.22 | B26: Are any current security capabilities provided by outsourced vendors or managed security service providers? | C26: Level 4 - Managed
A27: 2.2 - Training
A28: 2.2.1 | B28: Is there a defined annual training plan for SOC analysts? | C28: Level 5 - Optimized | H28: 4 | I28: 5
A29: 2.2.2 | B29: Is there a training budget allocated for SOC training? | C29: Level 5 - Optimized | H29: 4 | I29: 5
A30: 2.2.3 | B30: Is a list of preferred training documented? | C30: Level 5 - Optimized | H30: 4 | I30: 5
A31: 2.2.4 | B31: How regular are SOC analysts trained on threat scenarios? | C31: Level 5 - Optimized | H31: 4 | I31: 5
A32: 2.2.5 | B32: How regular are SOC analysts trained on SOC tools? | C32: Level 5 - Optimized | H32: 4 | I32: 5
A33: 2.2.6 | B33: How regular are SOC analysts refreshed on evidence handling and maintaining chain of custody? | C33: Level 5 - Optimized | H33: 4 | I33: 5
A34: 2.2.7 | B34: Are SOC analysts allowed to attend security conferences to expand knowledge on emerging threats? | C34: Level 5 - Optimized | H34: 4 | I34: 5
A35: 2.2.8 | B35: Is there a reference library in the SOC? | C35: Level 5 - Optimized | H35: 4 | I35: 5
A36: 2.2.9 | B36: Is there required training for all new analysts? | C36: Level 5 - Optimized | H36: 4 | I36: 5
A37: 2.2.10 | B37: Is there a system in place to evaluate analyst comprehension of new training? | C37: Level 5 - Optimized | H37: 4 | I37: 5
A38: 2.2.11 | B38: Is there any process in place to revisit analysts training as a refresher? | C38: Level 5 - Optimized | H38: 4 | I38: 5
A39: 2.2.12 | B39: Is any research done to find external training that may be beneficial to the SOC? | C39: Level 5 - Optimized | H39: 4 | I39: 5
... A47: 2.2.20 | B47: Is there formal training on critical business processes? Change Control, Time Tracking, etc… | C47: Level 5 - Optimized | H47: 4 | I47: 5
A48: 2.3 - Certifications
...

Sheet 3 - Process
A2: 3 - Process Control Objectives
A3: Index | B3: Control Objective | C3: Current | D3: Peer | E3: Recommended | F3: Maximum | G3: Peer | H3: Recommended | I3: Maximum | R3: Comments
A4: 3.1 - SOC Threat Management
A5: 3.1.1 | B5: Does the organization have a capability to real time capability to monitor for perimeter threats? | C5: Level 4 - Managed | H5: 4 | I5: 5 | J5: IPS coverage is only very limited to certains clients at the moment. | R5: Firewall logs being forwarded to SIEM. Rules configured to monitor network based attacks. Prevention mechanisms (e.g. IPS) does not exists.
A6: 3.1.2 | B6: Does the organization have a capability to real time capability to monitor for insider threats? | C6: Level 4 - Managed | H6: 4 | I6: 5 | K6: Vulnerability and Threat Management Report (Aaron Morrison). Target state micro/macro designs. Part of the Threat and Vulnerability Pillar
A7: 3.1.3 | B7: Does the organization have a capability to real time capability to monitor for DDoS threats? | C7: Level 4 - Managed | H7: 4 | I7: 5 | R7: Firewall logs being forwarded to SIEM. Rules configured to monitor DDoS attacks. Prevention mechanisms (e.g. DDoS devices) does not exists.
A8: 3.1.4 | B8: Does the organization have a capability to real time capability to monitor for Persistent Threats? | C8: Level 4 - Managed | H8: 4 | I8: 5 | R8: EDR agents installed on all the systems to prevent/ detect persistent attacks. EDR logs are currently not forwarded to SIEM (integration is in progress).
A9: 3.1.5 | B9: Does the organization have a capability to real time capability to monitor for Supply Chain Threats? | C9: Level 3 - Defined | H9: 4 | I9: 5
A10: 3.1.6 | B10: Does a formalized CSIRT exist? | C10: Level 2 - Repeatable | H10: 4 | I10: 5 | J10: CSIRT function is defined as part of the Enterprise Incidenet Management function | K10: Adhoc at this stage. No real documentation. ESCF shows evidence but no documentation found. Security Incident Handling Procedure Document?
A11: 3.1.7 | B11: Does the Threat Monitoring capability have formalized integration with CSIRT? | C11: Level 3 - Defined | H11: 4 | I11: 5
A12: 3.1.8 | B12: Does the organization have a formalized threat determination and development methodology that is used by the Threat Monitoring capability? | C12: Level 4 - Managed | H12: 4 | I12: 5 | K12: Speak to Aaron Morrison. | R12: New usecases are created and configured based on threat intelligence inputs
A13: 3.1.9 | B13: Testing for unvalidated input | C13: Level 4 - Managed | H13: 4 | I13: 5 | J13: The security o[perations team has a tool to run scans against new websites. | R13: Detected and Prevented by AKAMAI WAF
A14: 3.1.10 | B14: Testing for broken access control | C14: Level 4 - Managed | H14: 4 | I14: 5 | R14: Detected and Prevented by AKAMAI WAF
A15: 3.1.11 | B15: Testing for broken authentication control and session management | C15: Level 4 - Managed | H15: 4 | I15: 5 | R15: Detected and Prevented by AKAMAI WAF
A16: 3.1.12 | B16: Testing for secure communications | C16: Level 4 - Managed | H16: 4 | I16: 5 | R16: Detected and Prevented by AKAMAI WAF
A17: 3.1.13 | B17: Testing for cross site scripting attacks | C17: Level 4 - Managed | H17: 4 | I17: 5 | J17: The security o[perations team has a tool to run scans against new websites. | R17: Detected and Prevented by AKAMAI WAF
A18: 3.1.14 | B18: Perform monthly review of PRA process effectiveness | H18: 4 | I18: 5 | K18: Peronnel Risk Assessment. Yes to access reviews on quarterly basis. Not specific to Personnel risk based on roles. Network access specific only. All done by ETS for Service Operations (Paul Barry). Information Security Framework.
A19: 3.1.15 | B19: Perform monthly review of Cyber Training process effectiveness | C19: Level 5 - Optimized | H19: 4 | I19: 5 | K19: Rivka might refer to induction material
A20: 3.1.16 | B20: Does the SOC provide role based access to audit logs based on a "need to know" basis | C20: Level 5 - Optimized | H20: 4 | I20: 5 | J20: Security Operations currently does not collect logs.
A21: 3.1.17 | B21: Does the SOC generate alarm conditions based on Sample Company risk/threat use cases in real time | C21: Level 5 - Optimized | H21: 4 | I21: 5 | J21: Threat management process has no direct links to real time monitoring.
A22: 3.1.18 | B22: Does the SOC generate alarm conditions based on Sample Company specfied ESCF risk/threat use cases in real time | C22: Level 5 - Optimized | H22: 4 | I22: 5 | J22: Security Operations currently aligns with a Security framework, and is only just trying to more to ESCF.
A23: 3.1.19 | B23: Does the SOC generate an alarm condition for new vulnerability detected on critical/sensitive networks | C23: Level 3 - Defined | H23: 4 | I23: 5 | J23: No logs are collected for real time monitoring. | R23: VMS solution is not integrated with SOC
A24: 3.1.20 | B24: Does the SOC generate an alarm condition for new port and service detected on critical/sensitive networks | C24: Level 3 - Defined | H24: 4 | I24: 5 | J24: No logs are collected for real time monitoring. | R24: Network scanning solution is not integrated with SOC
A25: 3.1.21 | B25: Does the SOC correlate configuration changes against change management approved tickets | C25: Level 2 - Repeatable | H25: 4 | I25: 5 | J25: No logs are collected for real time monitoring. | R25: SOC team does not receive the change approved tickets
A26: 3.1.22 | B26: Does the SOC generate an alarm condition when a default/vendor account has been used | C26: Level 0 - Does not exist | H26: 4 | I26: 5 | J26: No logs are collected for real time monitoring.
A27: 3.1.23 | B27: Does the SOC generate an alarm condition when an account has been shared | C27: Level 0 - Does not exist | H27: 4 | I27: 5 | J27: No logs are collected for real time monitoring.
A28: 3.1.24 | B28: Does the SOC generate an alarm condition when an expired/disabled user account has been accessed | C28: Level 5 - Optimized | H28: 4 | I28: 5 | J28: No logs are collected for real time monitoring.
A29: 3.1.25 | B29: Does the SOC generate an alarm condition when a previous employees user account has been accessed | C29: Level 5 - Optimized | H29: 4 | I29: 5 | J29: No logs are collected for real time monitoring.
A30: 3.1.26 | B30: Does the SOC prioritize alarming based on value to the business | C30: Level 5 - Optimized | H30: 4 | I30: 5 | J30: No logs are collected for real time monitoring.
A31: 3.1.27 | B31: Does the SOC generate alarm in instances of unauthorized configuration changes | C31: Level 2 - Repeatable | H31: 4 | I31: 5 | J31: No logs are collected for real time monitoring.
A32: 3.1.28 | B32: Does the SOC generate an alarm for anomolous or unauthorized access controls | C32: Level 4 - Managed | H32: 4 | I32: 5 | J32: No logs are collected for real time monitoring.
A33: 3.1.29 | B33: Does the SOC generate an alarm for anomolous network flow | C33: Level 5 - Optimized | H33: 4 | I33: 5 | J33: No logs are collected for real time monitoring.
A34: 3.1.30 | B34: Does the SOC generate an alarm for unauthorized maintenance or mis-use of privilege | C34: Level 4 - Managed | H34: 4 | I34: 5 | J34: No logs are collected for real time monitoring. | R34: Usecases enabled for privileged user login
A35: 3.1.31 | B35: Does the SOC generate an alarm on deviation from segregation of duties | C35: Level 0 - Does not exist | H35: 4 | I35: 5 | J35: No logs are collected for real time monitoring.
A36: 3.1.32 | B36: Does the SOC alarm on any failed log into the ESP | C36: Level 0 - Does not exist | H36: 4 | I36: 5 | R36: EP are not monitored for failed/ unauthorised login
A37: 3.1.33 | B37: Does the SOC alarm on any login attempt to the ESP that is not authorized | C37: Level 0 - Does not exist | H37: 4 | I37: 5 | R37: EP are not monitored for failed/ unauthorised login
A38: 3.1.34 | B38: SOC will alarm on attempts at or actual unauthorized accesses. | C38: Level 5 - Optimized | H38: 4 | I38: 5
A39: 3.1.35 | B39: Does the SOC alarm if a physical door, gate or window is opened outside of normal activity | C39: Level 0 - Does not exist | H39: 4 | I39: 5
A40: 3.1.36 | B40: Does the SOC alarm under unsual network flow or worm type activitity | C40: Level 5 - Optimized | H40: 4 | I40: 5
A41: 3.1.37 | B41: Does the SOC monitor unusual activity from AV and anti-malware devices | C41: Level 3 - Defined | H41: 4 | I41: 5 | J41: Security Operations has AV responsibilities. Some alarms are in place but no real time monitoring is in place.
...

Sheet 4 - Technology Functional
A2: 4 - Technology Control Objectives
A3: Index | B3: Control Objective | C3: Current | D3: Peer | E3: Recommended | F3: Maximum | G3: Comments
A4: 4.1 - Security Information and Event Management
A5: 4.1.1 | B5: Does a production SIEM capability exist? | C5: Level 5 - Optimized | E5: 4 | F5: 5
A6: 4.1.2 | B6: Does the SIEM address SOC availability requirements? | C6: Level 5 - Optimized | E6: 4 | F6: 5
A7: 4.1.3 | B7: Does a dev and sandbox environment for SIEM exist? | C7: Level 5 - Optimized | E7: 4 | F7: 5
A8: 4.1.4 | B8: How do you monitor infrastructure performance? (availability, throughout, latency, average > peak > surge) | C8: Level 5 - Optimized | E8: 4 | F8: 5
A9: 4.1.5 | B9: Do you monitor any of the product vendor monitoring consoles to supplement your SIEM? | C9: Level 0 - Does not exist | E9: 4 | F9: 5
A10: 4.1.6 | B10: Does the organization have a support contract with your vendor? | C10: Level 5 - Optimized | E10: 4 | F10: 5
A11: 4.1.7 | B11: Does the organization have remote access to the SIEM? VPN, web console, etc… | C11: Level 5 - Optimized | E11: 4 | F11: 5
A12: 4.1.8 | B12: Is your SIEM in a hardened data center? | C12: Level 5 - Optimized | E12: 4 | F12: 5
A13: 4.1.9 | B13: Is SIEM RBAC configured based on role and function for SOC analysts? | C13: Level 5 - Optimized | E13: 4 | F13: 5
A14: 4.1.10 | B14: Is RBAC reviewed and approved by the SOC management on an annual basis, at a minimum? | C14: Level 5 - Optimized | E14: 4 | F14: 5
A15: 4.1.11 | B15: Does the organization have a documented upgrade procedure? | C15: Level 5 - Optimized | E15: 4 | F15: 5
A16: 4.1.12 | B16: Are all internal data streams encrypted? (Network connections) | C16: Level 5 - Optimized | E16: 4 | F16: 5
... A23: 4.1.19 | B23: Has the case management system been updated with SOC specific fields | C23: Level 5 - Optimized | E23: 4 | F23: 5
A24: 4.1.20 | B24: Are the SIEM assets/services classified as critical and listed accordingly? | C24: Level 5 - Optimized
A25: 4.1.21 | B25: Is there a support model in place for SIEM users? | C25: Level 5 - Optimized
A26: 4.1.22 | B26: Is there a defined role and process for SIEM account/access management? | C26: Level 5 - Optimized
A27: 4.2 - Intelligence Correlation
A28: 4.2.1 | B28: Does the organization integrate and correlate against emerging threat intelligence? | C28: Level 5 - Optimized | E28: 4 | F28: 5
A29: 4.2.2 | B29: Does the organization integrate and correlate against exploit intelligence? | C29: Level 5 - Optimized | E29: 4 | F29: 5
A30: 4.2.3 | B30: Does the organization integrate and correlate against domain reputation? | C30: Level 5 - Optimized | E30: 4 | F30: 5
A31: 4.2.4 | B31: Does the organization integrate brand intelligence? | C31: Level 5 - Optimized | E31: 4 | F31: 5
A32: 4.2.5 | B32: Does the organization integrate and correlate against Malware Drone IP intelligence? | C32: Level 5 - Optimized | E32: 4 | F32: 5
A33: 4.2.6 | B33: Does the organization integrate and correlate against MX intelligence? | C33: Level 5 - Optimized | E33: 4 | F33: 5
A34: 4.2.7 | B34: Does the organization integrate and correlate against Tor Exit Node intelligence? | C34: Level 5 - Optimized | E34: 4 | F34: 5
A35: 4.2.8 | B35: Does the organization integrate and correlate against vulnerability context intelligence? | C35: Level 0 - Does not exist | E35: 4 | F35: 5 | G35: No integration with VMS
A36: 4.2.9 | B36: Does the organization integrate and correlate against malware binary intelligence? | C36: Level 5 - Optimized | E36: 4 | F36: 5
A37: 4.3 - Architecture
A38: 4.3.1 | B38: Is the SOC environment in an access control environment? | C38: Level 5 - Optimized | E38: 4 | F38: 5
A39: 4.3.2 | B39: Does IDS exist at the ingress of the Corporate network into the SOC? | C39: Level 5 - Optimized | E39: 4 | F39: 5
A40: 4.3.3 | B40: Does the SOC have an out of band Internet connection (e.g. cable or ADSL)? | C40: Level 5 - Optimized | E40: 4 | F40: 5
A41: 4.3.4 | B41: Does the SOC have dedicated situational awareness screens? | C41: Level 5 - Optimized | E41: 4 | F41: 5
A42: 4.3.5 | B42: Are these situational awareness screens visible from all SOC Level 1 analyst workstations? | C42: Level 5 - Optimized | E42: 4 | F42: 5
A43: 4.3.6 | B43: Are measures put in place that the main situational awareness screen cannot be tampered with? | C43: Level 5 - Optimized | E43: 4 | F43: 5
A44: 4.3.7 | B44: Does the organization have detailed and current architecture diagrams? | C44: Level 5 - Optimized | E44: 4 | F44: 5
A45: 4.3.8 | B45: Describe security measures for architecture: SIM/SEM, collection servers and endpoints. | C45: Level 5 - Optimized | E45: 4 | F45: 5
A46: 4.3.9 | B46: How do you provide high availability? Facilities (network, power, system redundancy). | C46: Level 5 - Optimized | E46: 4 | F46: 5
A47: 4.3.10 | B47: How is Information Security implemented for the entire architecture? | C47: Level 5 - Optimized | E47: 4 | F47: 5
...

Sheet 5 - Coverage
A2: 5 - Coverage
A3: Index | B3: Control Objective | C3: Current | D3: Peer | E3: Recommended | F3: Maximum | G3: Comments
A4: 5.1 - Infrastructure Event Coverage
A5: 5.1.1 | B5: Does the organization collect logs from File and Print Servers? | C5: Level 0 - Does not exist | E5: 4 | F5: 5
A6: 5.1.2 | B6: Does the organization collect logs from Application Servers? | C6: Level 4 - Managed | E6: 4 | F6: 5
A7: 5.1.3 | B7: Does the organization collect logs from NOS Authentication Servers (e.g. AD)? | C7: Level 5 - Optimized | E7: 4 | F7: 5
A8: 5.1.4 | B8: Does the organization classify and collect logs from critical servers? | C8: Level 5 - Optimized | E8: 4 | F8: 5
A9: 5.1.5 | B9: Does the organization classify and collect logs from servers that have classified data sets? | C9: Level 5 - Optimized | E9: 4 | F9: 5
A10: 5.1.6 | B10: Does the organization distinguish between classification between data sets (within the SOC)? | C10: Level 5 - Optimized | E10: 4 | F10: 5
A11: 5.1.7 | B11: Does the organization collect syslog from *NIX servers? | C11: Level 5 - Optimized | E11: 4 | F11: 5
A12: 5.1.8 | B12: Does the organization collect logs from enhanced auditing sub-sytems from *NIX (e.g. Solaris BSM)? | C12: Level 0 - Does not exist | E12: 4 | F12: 5
A13: 5.1.9 | B13: Does the organization collect logs from super user access control sub-systems? | C13: Level 5 - Optimized | E13: 4 | F13: 5
A14: 5.2 - Security Devices Coverage
A15: 5.2.1 | B15: Does the organization collect logs from firewall inspection points? | C15: Level 5 - Optimized | E15: 4 | F15: 5
A16: 5.2.2 | B16: Does the organization collect logs from management of firewalls (e.g. firewall admin logging)? | C16: Level 5 - Optimized | E16: 4 | F16: 5
A17: 5.2.3 | B17: Does the organization collect logs from the firewall OS (if applicable)? Please allocate 5 points if not applicable)? | C17: Level 5 - Optimized | E17: 4 | F17: 5
A18: 5.2.4 | B18: Does the organization collect logs from IDS/IPS? | C18: Level 0 - Does not exist | E18: 4 | F18: 5
A19: 5.2.5 | B19: Does the organization collect scan context from vulnerability scanners and use it for correlation)? | C19: Level 3 - Defined | E19: 4 | F19: 5 | G19: VMS Solution is not integrated
A20: 5.2.6 | B20: Does the organization collect port context from port scanners (and use it for correlation)? | C20: Level 5 - Optimized | E20: 4 | F20: 5
A21: 5.2.7 | B21: Does the organization collect web security context from web scanners (and use it for correlation)? | C21: Level 0 - Does not exist | E21: 4 | F21: 5
A22: 5.2.8 | B22: Does the organization collect logs from authentication servers? | C22: Level 5 - Optimized | E22: 4 | F22: 5
A23: 5.2.9 | B23: Does the organization collect logs from token authentication servers? | C23: Level 5 - Optimized | E23: 4 | F23: 5
A24: 5.2.10 | B24: Does the organization collect logs from Site to Site VPN's? | C24: Level 5 - Optimized | E24: 4 | F24: 5
A25: 5.2.11 | B25: Does the organization collect logs from SSL VPN's? | C25: Level 5 - Optimized | E25: 4 | F25: 5
A26: 5.2.12 | B26: Does the organization collect logs from external terminal servers (e.g. Citrix)? | C26: Level 5 - Optimized | E26: 4 | F26: 5
A27: 5.2.13 | B27: Does the organization collect logs from internal terminal servers? | C27: Level 5 - Optimized | E27: 4 | F27: 5
A28: 5.2.14 | B28: Does the organization collect logs from Wireless IDS and Rogue device detectors? | C28: Level 5 - Optimized | E28: 4 | F28: 5
A29: 5.2.15 | B29: Does the organization collect logs from file integrity sensors (e.g. Tripwire)? | C29: Level 0 - Does not exist | E29: 4 | F29: 5
A30: 5.2.16 | B30: Does the organization collect logs from Password Vaulting systems? | C30: Level 5 - Optimized | E30: 4 | F30: 5
A31: 5.3 - Advanced Threat Coverage
A32: 5.3.1 | B32: Does the organization collect logs from web content inspection devices? | C32: Level 0 - Does not exist | E32: 4 | F32: 5
A33: 5.3.2 | B33: Does the organization collect logs from SMTP content inspection devices? | C33: Level 5 - Optimized | E33: 4 | F33: 5
A34: 5.3.3 | B34: Does the organization collect logs from network forensic devices? | C34: Level 0 - Does not exist | E34: 4 | F34: 5
A35: 5.3.4 | B35: Does the organization collect logs from malware analysis devices? | C35: Level 5 - Optimized | E35: 4 | F35: 5
A36: 5.3.5 | B36: Does the organization collect logs from proxy servers? | C36: Level 5 - Optimized | E36: 4 | F36: 5
A37: 5.3.6 | B37: Does the organization collect logs from DHCP servers? | C37: Level 5 - Optimized | E37: 4 | F37: 5
A38: 5.3.7 | B38: Does the organization collect logs from forwarding DNS? | C38: Level 5 - Optimized | E38: 4 | F38: 5
A39: 5.3.8 | B39: Does the organization collect logs from authoritative DNS? | C39: Level 5 - Optimized | E39: 4 | F39: 5
A40: 5.4 - Network Device Coverage
A41: 5.4.1 | B41: Does the organization collect logs from access level switches? | C41: Level 5 - Optimized | E41: 4 | F41: 5
...

Sheet 5.2 - SOC covered event sources
A2: 5.2 - Event Source Coverage
A3: Please enter the current devices/event sources that are incorporated into the SOC
A4: Device vendor | B4: Device Product | C4: Region | D4: Coverage % | G4: Maximum
A5: Business Critical Assets (Assests should be identified in the Asset Model within SIEM)
G6: 5
G7: 5
G8: 5
G9: 5
G10: 5
G11: 5
G12: 5
G13: 5
G14: 5
G16: 5
G17: 5
G18: 5
... G20: 5
A21: Unclassified Assets
G22: 5
G23: 5
G24: 5
G25: 5
G26: 5
G27: 5
G28: 5
G29: 5
G30: 5
G31: 5
G33: 5
G34: 5
... G129: 5
B132: SUMMARY Score | D132: =#REF! -> #REF! | E132: =#REF! -> #REF! | F132: =#REF! -> #REF! | G132: =#REF! -> #REF!
B133: =A5 -> Business Critical Assets (Assests should be identified in the Asset Model within SIEM) | D133: =SUM(D6:D14) -> 0 | E133: =SUM(E6:E14) -> 0 | F133: =SUM(F6:F14) -> 0 | G133: =SUM(G6:G14) -> 45
B134: =A15 -> 0 | D134: =SUM(D16:D31) -> 0 | E134: =SUM(E16:E31) -> 0 | F134: =SUM(F16:F31) -> 0 | G134: =SUM(G16:G31) -> 75
B135: =A32 -> 0 | D135: =SUM(D33:D40) -> 0 | E135: =SUM(E33:E40) -> 0 | F135: =SUM(F33:F40) -> 0 | G135: =SUM(G33:G40) -> 40
B136: =A41 -> 0 | D136: =SUM(D42:D54) -> 0 | E136: =SUM(E42:E54) -> 0 | F136: =SUM(F42:F54) -> 0 | G136: =SUM(G42:G54) -> 65
B137: =A55 -> 0 | D137: =SUM(D56:D59) -> 0 | E137: =SUM(E56:E59) -> 0 | F137: =SUM(F56:F59) -> 0 | G137: =SUM(G56:G59) -> 20
B138: =A60 -> 0 | D138: =SUM(D61:D98) -> 0 | E138: =SUM(E61:E98) -> 0 | F138: =SUM(F61:F98) -> 0 | G138: =SUM(G61:G98) -> 190
B139: =A99 -> 0 | D139: =SUM(D100:D129) -> 0 | E139: =SUM(E100:E129) -> 0 | F139: =SUM(F100:F129) -> 0 | G139: =SUM(G100:G129) -> 150
B140: TOTAL | D140: =SUM(D133:D139) -> 0 | E140: =SUM(E133:E139) -> 0 | F140: =SUM(F133:F139) -> 0 | G140: =SUM(G133:G139) -> 585
...

Sheet 5.3 - Overall Inventory
A2: 5.3 - Overall Inventory
A3: Please enter numbers of the complete inventory at the organization. Typical this can be obtained from a CMDB, Asset Management etc.. It is recommended that this information should be gathered from non SOC sources (e.g. Operational Teams). Please refer to the worksheet "Sample Event Scope" for sample event sources.
A4: Device vendor | B4: Device Product | C4: Region | D4: Coverage % | G4: Maximum
A5: Business Critical Assets
G6: 5
G7: 5
G8: 5
G9: 5
G10: 5
G11: 5
G12: 5
G13: 5
G14: 5
G16: 5
G17: 5
G18: 5
... G20: 5
A21: Unclassified Assets
G22: 5
G23: 5
G24: 5
G25: 5
G26: 5
G27: 5
G28: 5
G29: 5
G30: 5
G31: 5
G33: 5
G34: 5
... G129: 5
B132: SUMMARY Score | D132: =#REF! -> #REF! | E132: =#REF! -> #REF! | F132: =#REF! -> #REF! | G132: =#REF! -> #REF!
B133: =A5 -> Business Critical Assets | D133: =SUM(D6:D14) -> 0 | E133: =SUM(E6:E14) -> 0 | F133: =SUM(F6:F14) -> 0 | G133: =SUM(G6:G14) -> 45
B134: =A15 -> 0 | D134: =SUM(D16:D31) -> 0 | E134: =SUM(E16:E31) -> 0 | F134: =SUM(F16:F31) -> 0 | G134: =SUM(G16:G31) -> 75
B135: =A32 -> 0 | D135: =SUM(D33:D40) -> 0 | E135: =SUM(E33:E40) -> 0 | F135: =SUM(F33:F40) -> 0 | G135: =SUM(G33:G40) -> 40
B136: =A41 -> 0 | D136: =SUM(D42:D54) -> 0 | E136: =SUM(E42:E54) -> 0 | F136: =SUM(F42:F54) -> 0 | G136: =SUM(G42:G54) -> 65
B137: =A55 -> 0 | D137: =SUM(D56:D59) -> 0 | E137: =SUM(E56:E59) -> 0 | F137: =SUM(F56:F59) -> 0 | G137: =SUM(G56:G59) -> 20
B138: =A60 -> 0 | D138: =SUM(D61:D98) -> 0 | E138: =SUM(E61:E98) -> 0 | F138: =SUM(F61:F98) -> 0 | G138: =SUM(G61:G98) -> 190
B139: =A99 -> 0 | D139: =SUM(D100:D129) -> 0 | E139: =SUM(E100:E129) -> 0 | F139: =SUM(F100:F129) -> 0 | G139: =SUM(G100:G129) -> 150
B140: TOTAL | D140: =SUM(D133:D139) -> 0 | E140: =SUM(E133:E139) -> 0 | F140: =SUM(F133:F139) -> 0 | G140: =SUM(G133:G139) -> 585
...

Sheet Sample Event Scope
K2: Phase 1 | P2: Phase 2
A3: Phase | B3: Devices | C3: Identify Vendors if needed | D3: Versions (kernel if relative) | E3: Quantity | F3: Datacenter#1 | G3: Datacenter#2 | H3: Datacenter#3 | K3: Phase 1 Scope | L3: Phase 1 Count | M3: =F3 -> Datacenter#1 | N3: =G3 -> Datacenter#2 | O3: =H3 -> Datacenter#3 | P3: Phase 2 Scope | Q3: Phase 2 Count | R3: =F3 -> Datacenter#1 | S3: =G3 -> Datacenter#2 | T3: =H3 -> Datacenter#3
A4: INF | B4: Windows Servers | E4: =SUM(H4,G4,F4) -> 1973 | F4: 398 | G4: 773 | H4: 802 | K4: 0 | L4: =E4*K4 -> 0 | M4: =F4*$K4 -> 0 | N4: =G4*$K4 -> 0 | O4: =H4*$K4 -> 0 | P4: 0 | Q4: =P4*E4 -> 0 | R4: =$P4*F4 -> 0 | S4: =$P4*G4 -> 0 | T4: =$P4*H4 -> 0
A5: INF | B5: Windows Servers | C5: 2000 | E5: =SUM(H5,G5,F5) -> 132 | F5: 46 | G5: 50 | H5: 36 | L5: =E5*K5 -> 0 | M5: =F5*$K5 -> 0 | N5: =G5*$K5 -> 0 | O5: =H5*$K5 -> 0 | P5: 0.05 | Q5: =P5*E5 -> 6.6 | R5: =$P5*F5 -> 2.3 | S5: =$P5*G5 -> 2.5 | T5: =$P5*H5 -> 1.8
A6: INF | B6: Windows Servers | C6: 2003 | E6: =SUM(H6,G6,F6) -> 1324 | F6: 234 | G6: 509 | H6: 581 | L6: =E6*K6 -> 0 | M6: =F6*$K6 -> 0 | N6: =G6*$K6 -> 0 | O6: =H6*$K6 -> 0 | P6: 0.05 | Q6: =P6*E6 -> 66.2 | R6: =$P6*F6 -> 11.7 | S6: =$P6*G6 -> 25.45 | T6: =$P6*H6 -> 29.05
A7: INF | B7: Windows Servers | C7: 2008 | E7: =SUM(H7,G7,F7) -> 517 | F7: 118 | G7: 214 | H7: 185 | L7: =E7*K7 -> 0 | M7: =F7*$K7 -> 0 | N7: =G7*$K7 -> 0 | O7: =H7*$K7 -> 0 | P7: 0.05 | Q7: =P7*E7 -> 25.85 | R7: =$P7*F7 -> 5.9 | S7: =$P7*G7 -> 10.7 | T7: =$P7*H7 -> 9.25
A8: INF | B8: Unix Server | C8: HPUX | D8: 11.11, 11.23 | E8: =SUM(H8,G8,F8) -> 108 | F8: 33 | G8: 64 | H8: 11 | K8: 0.05 | L8: =E8*K8 -> 5.4 | M8: =F8*$K8 -> 1.65 | N8: =G8*$K8 -> 3.2 | O8: =H8*$K8 -> 0.55 | P8: 0.95 | Q8: =P8*E8 -> 102.6 | R8: =$P8*F8 -> 31.35 | S8: =$P8*G8 -> 60.8 | T8: =$P8*H8 -> 10.45
A9: INF | B9: Unix Server | C9: Solaris | D9: 7, 8, 9, 10 | E9: =SUM(H9,G9,F9) -> 34 | F9: 0 | G9: 0 | H9: 34 | L9: =E9*K9 -> 0 | M9: =F9*$K9 -> 0 | N9: =G9*$K9 -> 0 | O9: =H9*$K9 -> 0 | P9: 0.05 | Q9: =P9*E9 -> 1.7 | R9: =$P9*F9 -> 0 | S9: =$P9*G9 -> 0 | T9: =$P9*H9 -> 1.7
A10: INF | B10: Unix Server | C10: AIX | D10: 5.2, 6.1 | E10: =SUM(H10,G10,F10) -> 50 | F10: 0 | G10: 48 | H10: 2 | L10: =E10*K10 -> 0 | M10: =F10*$K10 -> 0 | N10: =G10*$K10 -> 0 | O10: =H10*$K10 -> 0 | P10: 0.05 | Q10: =P10*E10 -> 2.5 | R10: =$P10*F10 -> 0 | S10: =$P10*G10 -> 2.4 | T10: =$P10*H10 -> 0.1
A11: 2 | B11: DNS Server (BIND) | C11: BIND | E11: =SUM(H11,G11,F11) -> 3 | F11: 1 | G11: 1 | H11: 1 | L11: =E11*K11 -> 0 | M11: =F11*$K11 -> 0 | N11: =G11*$K11 -> 0 | O11: =H11*$K11 -> 0 | P11: 1 | Q11: =P11*E11 -> 3 | R11: =$P11*F11 -> 1 | S11: =$P11*G11 -> 1 | T11: =$P11*H11 -> 1
A12: INF | B12: Mail Filtering (IronMail) | E12: =SUM(H12,G12,F12) -> 4 | F12: 0 | G12: 2 | H12: 2 | L12: =E12*K12 -> 0 | M12: =F12*$K12 -> 0 | N12: =G12*$K12 -> 0 | O12: =H12*$K12 -> 0 | P12: 1 | Q12: =P12*E12 -> 4 | R12: =$P12*F12 -> 0 | S12: =$P12*G12 -> 2 | T12: =$P12*H12 -> 2
A13: INF | B13: Load Balancers (Cisco) | E13: =SUM(H13,G13,F13) -> 5 | F13: 2 | G13: 3 | H13: 0 | L13: =E13*K13 -> 0 | M13: =F13*$K13 -> 0 | N13: =G13*$K13 -> 0 | O13: =H13*$K13 -> 0 | P13: 1 | Q13: =P13*E13 -> 5 | R13: =$P13*F13 -> 2 | S13: =$P13*G13 -> 3 | T13: =$P13*H13 -> 0
A14: INF | B14: Load Balancers (F5) | E14: =SUM(H14,G14,F14) -> 7 | F14: 1 | G14: 4 | H14: 2 | L14: =E14*K14 -> 0 | M14: =F14*$K14 -> 0 | N14: =G14*$K14 -> 0 | O14: =H14*$K14 -> 0 | P14: 1 | Q14: =P14*E14 -> 7 | R14: =$P14*F14 -> 1 | S14: =$P14*G14 -> 4 | T14: =$P14*H14 -> 2
A15: INF | B15: Linux Servers | D15: multiple (please review comments) | E15: =SUM(H15,G15,F15) -> 196 | F15: 33 | G15: 44 | H15: 119 | L15: =E15*K15 -> 0 | M15: =F15*$K15 -> 0 | N15: =G15*$K15 -> 0 | O15: =H15*$K15 -> 0 | P15: 1 | Q15: =P15*E15 -> 196 | R15: =$P15*F15 -> 33 | S15: =$P15*G15 -> 44 | T15: =$P15*H15 -> 119
A16: 2 | B16: VMWare Servers | E16: =SUM(H16,G16,F16) -> 105 | F16: 30 | G16: 44 | H16: 31 | L16: =E16*K16 -> 0 | M16: =F16*$K16 -> 0 | N16: =G16*$K16 -> 0 | O16: =H16*$K16 -> 0 | P16: 1 | Q16: =P16*E16 -> 105 | R16: =$P16*F16 -> 30 | S16: =$P16*G16 -> 44 | T16: =$P16*H16 -> 31
